Workbook
Name AMF12M: OFFSET('[1]LR charts'!$AI$116,0,0,COUNT('[1]LR charts'!$AI$1:$AI$65536)-109,1)
Name AMF5YR: OFFSET('[1]LR charts'!$AI$67,0,0,COUNT('[1]LR charts'!$AI$1:$AI$65536)-60,1)
Name cost: #REF!
Name cost: #REF!
Name cost: #REF!
Name cost: #REF!
Name date: #REF!
Name date: #REF!
Name date: #REF!
Name date: #REF!
Name LacEth: #REF!
Name LacEth: #REF!
Name LacEth: #REF!
Name LacEth: #REF!
Name MilkpermBS: #REF!
Name MilkpermBS: #REF!
Name MilkpermBS: #REF!
Name MilkpermBS: #REF!
Name MilkpermCas: #REF!
Name MilkpermCas: #REF!
Name MilkpermCas: #REF!
Name MilkpermCas: #REF!
Name MilkpermDS: #REF!
Name MilkpermDS: #REF!
Name MilkpermDS: #REF!
Name MilkpermDS: #REF!
Name MilkpermLC: #REF!
Name MilkpermLC: #REF!
Name MilkpermLC: #REF!
Name MilkpermLC: #REF!
Name milkpermMPC70: #REF!
Name milkpermMPC70: #REF!
Name milkpermMPC70: #REF!
Name milkpermMPC70: #REF!
Name MilkpermRC: #REF!
Name MilkpermRC: #REF!
Name MilkpermRC: #REF!
Name MilkpermRC: #REF!
Name SMP12M: OFFSET('[1]LR charts'!$AL$116,0,0,COUNT('[1]LR charts'!$AL$1:$AL$65536)-109,1)
Name SMP5Yr: OFFSET('[1]LR charts'!$AL$67,0,0,COUNT('[1]LR charts'!$AL$1:$AL$65536)-60,1)
Name WMP5Yr: OFFSET('[1]LR charts'!$AN$67,0,0,COUNT('[1]LR charts'!$AN$1:$AN$65536)-60,1)
Name WMPGraph: OFFSET('[1]LR charts'!$AN$67,0,0,COUNT('[1]LR charts'!$AN$1:$AN$65536)-60,1)

Sheet BMC and Milk Procurement
E1: 2011-12 | F1: 2012-13 | G1: 2013-14 | H1: 2014-15 | I1: 2015-16 | J1: 2016-17 | K1: 2017-18 | L1: 2018-19 | M1: 2019-20 | N1: 2020-21 | O1: 2021-22 | P1: 2022-23 | Q1: 2023-24 | R1: 2024-25 | S1: 2025-26 | T1: 2026-27 | U1: 2027-28 | V1: 2028-29 | W1: 2029-30 | X1: 2030-31 | Y1: 2031-32 | Z1: 2032-33 | AA1: 2033-34 | AB1: 2034-35 | AC1: 2036-37
A2: Operating Expense
A3: Bull Production-PT | B3: Million Rupees | E3: 95.81198 | F3: 113.36445 | G3: 130.45873 | H3: 145.31488 | I3: 153.27316 | J3: 164.78352 | K3: =J3 -> 164.78352 | L3: =K3 -> 164.78352 | M3: =L3 -> 164.78352 | N3: =M3 -> 164.78352 | O3: =N3 -> 164.78352 | P3: =O3 -> 164.78352 | Q3: =P3 -> 164.78352 | R3: =Q3 -> 164.78352 | ... AC3: =AB3 -> 164.78352
A4: Breed Improvement | B4: Million Rupees | E4: 20.44365 | F4: 36.39845 | G4: 40.498876 | H4: 44.048538 | I4: 44.91477 | J4: 46.565408 | K4: =J4 -> 46.565408 | L4: =K4 -> 46.565408 | M4: =L4 -> 46.565408 | N4: =M4 -> 46.565408 | O4: =N4 -> 46.565408 | P4: =O4 -> 46.565408 | Q4: =P4 -> 46.565408 | R4: =Q4 -> 46.565408 | ... AC4: =AB4 -> 46.565408
A5: Semen Production | B5: Million Rupees | E5: =SUM(E6:E7) -> 55.197528 | F5: =SUM(F6:F7) -> 121.06552 | G5: =SUM(G6:G7) -> 132.84173 | H5: =SUM(H6:H7) -> 135.88708 | I5: =SUM(I6:I7) -> 140.82006 | J5: =SUM(J6:J7) -> 148.75277 | K5: =SUM(K6:K7) -> 157.36785 | L5: =SUM(L6:L7) -> 162.80511 | ... AC5: =SUM(AC6:AC7) -> 163.69464
A6: Training: Strengthening SS | B6: Million Rupees | E6: 0 | F6: 5.9555556 | G6: 5.9555556 | H6: 0 | I6: 0 | J6: 0
A7: New Semen Stations | B7: Million Rupees | E7: =SUM(E82:E85) -> 55.197528 | F7: =SUM(F82:F85) -> 115.10997 | G7: =SUM(G82:G85) -> 126.88618 | H7: =SUM(H82:H85) -> 135.88708 | I7: =SUM(I82:I85) -> 140.82006 | J7: =SUM(J82:J85) -> 148.75277 | K7: =SUM(K82:K85) -> 157.36785 | L7: =SUM(L82:L85) -> 162.80511 | ... AC7: =SUM(AC82:AC85) -> 163.69464
A8: Import of Bulls | B8: Million Rupees | E8: 111.11111 | F8: 111.11111 | G8: 0 | H8: 111.11111 | I8: 0 | J8: 111.11111 | K8: 0 | L8: 0 | M8: 0 | N8: 0 | O8: 0 | P8: 0 | Q8: 0 | R8: 0 | S8: 0 | T8: 0 | U8: 0 | V8: 0 | W8: 0 | X8: 0 | Y8: 0 | Z8: 0 | AA8: 0 | AB8: 0 | AC8: 0
A9: AI Delivery | B9: Million Rupees | E9: 131.646 | F9: 417.1645 | G9: 786.7945 | H9: 611.0008 | I9: 589.5436 | J9: 569.138 | K9: =J9 -> 569.138 | L9: =K9 -> 569.138 | M9: =L9 -> 569.138 | N9: =M9 -> 569.138 | O9: =N9 -> 569.138 | P9: =O9 -> 569.138 | Q9: =P9 -> 569.138 | R9: =Q9 -> 569.138 | ... AC9: =AB9 -> 569.138
A10: LN Delivery | B10: Million Rupees | E10: 0 | F10: 0.04908 | G10: 0.04499 | H10: 0.04499 | I10: 0.01636 | J10: 0 | K10: 0 | L10: 0 | M10: 0 | N10: 0 | O10: 0 | P10: 0 | Q10: 0 | R10: 0 | S10: 0 | T10: 0 | U10: 0 | V10: 0 | W10: 0 | X10: 0 | Y10: 0 | Z10: 0 | AA10: 0 | AB10: 0 | AC10: 0
A11: Information system | B11: Million Rupees | E11: 23.57 | F11: 23.626 | G11: 23.579 | H11: 23.524 | I11: 23.413 | J11: 23.413 | K11: 0 | L11: =K11 -> 0 | M11: =L11 -> 0 | N11: =M11 -> 0 | O11: =N11 -> 0 | P11: =O11 -> 0 | Q11: =P11 -> 0 | R11: =Q11 -> 0 | S11: =R11 -> 0 | ... AC11: =AB11 -> 0
A12: Animal Health | B12: Million Rupees | E12: 0 | F12: 0 | G12: 0 | H12: 0 | I12: 0 | J12: 0 | K12: 0 | L12: =K12 -> 0 | M12: =L12 -> 0 | N12: =M12 -> 0 | O12: =N12 -> 0 | P12: =O12 -> 0 | Q12: =P12 -> 0 | R12: =Q12 -> 0 | S12: =R12 -> 0 | ... AC12: =AB12 -> 0
A13: Heifer Rearing | B13: Million Rupees | E13: 12.272 | F13: 22.012 | G13: 31.312 | H13: 15.26 | I13: 11.36 | J13: 11.36 | K13: =J13 -> 11.36 | L13: =K13 -> 11.36 | M13: =L13 -> 11.36 | N13: =M13 -> 11.36 | O13: =N13 -> 11.36 | P13: =O13 -> 11.36 | Q13: =P13 -> 11.36 | R13: =Q13 -> 11.36 | ... AC13: =AB13 -> 11.36
A14: RBP | B14: Million Rupees | E14: =E92 -> 154.64111 | F14: =F92 -> 417.66303 | G14: =G92 -> 642.83917 | H14: =H92 -> 690.5323 | I14: =I92 -> 575.68596 | J14: =J92 -> 268.88586 | K14: =K92 -> 268.88586 | L14: =L92 -> 268.88586 | ... AC14: =AC92 -> 268.88586
A15: Fodder Development | B15: Million Rupees | E15: 35.27 | F15: 152.579 | G15: 180.596 | H15: 268.4195 | I15: 282.0975 | J15: 290.551 | K15: =J15 -> 290.551 | L15: =K15 -> 290.551 | M15: =L15 -> 290.551 | N15: =M15 -> 290.551 | O15: =N15 -> 290.551 | P15: =O15 -> 290.551 | Q15: =P15 -> 290.551 | R15: =Q15 -> 290.551 | ... AC15: =AB15 -> 290.551
A16: Milk Collection and Bulking | B16: Million Rupees | E16: =E108 -> #REF! | F16: =F108 -> #REF! | G16: =G108 -> #REF! | H16: =H108 -> #REF! | I16: =I108 -> #REF! | J16: =J108 -> #REF! | K16: =K108 -> #REF! | L16: =L108 -> #REF! | ... AC16: =AC108 -> #REF!
A17: Total Incremental Costs | B17: Million Rupees | E17: =SUM(E3,E4,E5,E8,E9,E10,E11,E12,E13,E14,E15,E16) -> #REF! | F17: =SUM(F3,F4,F5,F8,F9,F10,F11,F12,F13,F14,F15,F16) -> #REF! | G17: =SUM(G3,G4,G5,G8,G9,G10,G11,G12,G13,G14,G15,G16) -> #REF! | H17: =SUM(H3,H4,H5,H8,H9,H10,H11,H12,H13,H14,H15,H16) -> #REF! | I17: =SUM(I3,I4,I5,I8,I9,I10,I11,I12,I13,I14,I15,I16) -> #REF! | J17: =SUM(J3,J4,J5,J8,J9,J10,J11,J12,J13,J14,J15,J16) -> #REF! | K17: =SUM(K3,K4,K5,K8,K9,K10,K11,K12,K13,K14,K15,K16) -> #REF! | L17: =SUM(L3,L4,L5,L8,L9,L10,L11,L12,L13,L14,L15,L16) -> #REF! | ... AC17: =SUM(AC3,AC4,AC5,AC8,AC9,AC10,AC11,AC12,AC13,AC14,AC15,AC16) -> #REF!
A20: CAPITAL INVESTMENT
A23: Bull Production through PT | B23: Million Rupees | C23: 1 | E23: 119.185 | F23: 34.7 | G23: 11.559 | H23: 14.411 | I23: 10.457 | J23: 14.392
E24: =E23*$C$23 -> 119.185 | F24: =F23*$C$23 -> 34.7 | G24: =G23*$C$23 -> 11.559 | H24: =H23*$C$23 -> 14.411 | I24: =I23*$C$23 -> 10.457 | J24: =J23*$C$23 -> 14.392 | K24: =K23*$C$23 -> 0 | L24: =L23*$C$23 -> 0 | ... AC24: =AC23*$C$23 -> 0
A25: Import of bulls | B25: Million Rupees | C25: 0 | E25: 0 | F25: 0 | G25: 0 | H25: 0 | I25: 0 | J25: 0
E26: =E25*$C$25 -> 0 | F26: =F25*$C$25 -> 0 | G26: =G25*$C$25 -> 0 | H26: =H25*$C$25 -> 0 | I26: =I25*$C$25 -> 0 | J26: =J25*$C$25 -> 0 | K26: =K25*$C$25 -> 0 | L26: =L25*$C$25 -> 0 | ... AC26: =AC25*$C$25 -> 0
A27: Breed Improvement | B27: Million Rupees | C27: 1 | E27: 6.269 | F27: 6.782 | G27: 6.558 | H27: 2.332 | I27: 0 | J27: 0
E28: =E27*$C$27 -> 6.269 | F28: =F27*$C$27 -> 6.782 | G28: =G27*$C$27 -> 6.558 | H28: =H27*$C$27 -> 2.332 | I28: =I27*$C$27 -> 0 | J28: =J27*$C$27 -> 0 | K28: =K27*$C$27 -> 0 | L28: =L27*$C$27 -> 0 | ... AC28: =AC27*$C$27 -> 0
A29: Semen Production | B29: Million Rupees | C29: 1 | E29: =E80 -> 687.5873 | F29: =F80 -> 571.7036 | G29: =G80 -> 112.21981 | H29: =H80 -> 15.015 | I29: =I80 -> 0.378 | J29: =J80 -> 0.1575
E30: =E29*$C$29 -> 687.5873 | F30: =F29*$C$29 -> 571.7036 | G30: =G29*$C$29 -> 112.21981 | H30: =H29*$C$29 -> 15.015 | I30: =I29*$C$29 -> 0.378 | J30: =J29*$C$29 -> 0.1575 | K30: =K29*$C$29 -> 0 | L30: =L29*$C$29 -> 0 | ... AC30: =AC29*$C$29 -> 0
A31: AI Delivery | B31: Million Rupees | C31: 1 | E31: 104.788 | F31: 207.692 | G31: 313.832 | H31: 82.104 | I31: 54.504 | J31: 54.504
E32: =E31*$C$31 -> 104.788 | F32: =F31*$C$31 -> 207.692 | G32: =G31*$C$31 -> 313.832 | H32: =H31*$C$31 -> 82.104 | I32: =I31*$C$31 -> 54.504 | J32: =J31*$C$31 -> 54.504 | K32: =K31*$C$31 -> 0 | L32: =L31*$C$31 -> 0 | ... AC32: =AC31*$C$31 -> 0
A33: LN | B33: Million Rupees | C33: 1 | E33: 64.575 | F33: 62.47 | G33: 0 | H33: 0 | I33: 0 | J33: 0
E34: =E33*$C$33 -> 64.575 | F34: =F33*$C$33 -> 62.47 | G34: =G33*$C$33 -> 0 | H34: =H33*$C$33 -> 0 | I34: =I33*$C$33 -> 0 | J34: =J33*$C$33 -> 0 | K34: =K33*$C$33 -> 0 | L34: =L33*$C$33 -> 0 | ... AC34: =AC33*$C$33 -> 0
A35: Information Systems | B35: Million Rupees | C35: 1 | E35: 133.334 | F35: 22.223 | G35: 0 | H35: 33.334 | I35: 0 | J35: 0
E36: =E35*$C$35 -> 133.334 | F36: =F35*$C$35 -> 22.223 | G36: =G35*$C$35 -> 0 | H36: =H35*$C$35 -> 33.334 | I36: =I35*$C$35 -> 0 | J36: =J35*$C$35 -> 0 | K36: =K35*$C$35 -> 0 | L36: =L35*$C$35 -> 0 | ... AC36: =AC35*$C$35 -> 0
A37: Animal Nutrition - RBP | B37: Million Rupees | C37: 1 | E37: 50.775 | F37: 115.79 | G37: 158.51 | H37: 145.133 | I37: 99.68 | J37: 0 | K37: 0 | L37: 0 | M37: 0 | N37: 0 | O37: 0 | P37: 0 | Q37: 0 | R37: 0 | S37: 0 | T37: 0 | U37: 0 | V37: 0 | W37: 0 | X37: 0 | Y37: 0 | Z37: 0 | AA37: 0 | AB37: 0 | AC37: 0
E38: =E37*$C$37 -> 50.775 | F38: =F37*$C$37 -> 115.79 | G38: =G37*$C$37 -> 158.51 | H38: =H37*$C$37 -> 145.133 | I38: =I37*$C$37 -> 99.68 | J38: =J37*$C$37 -> 0 | K38: =K37*$C$37 -> 0 | L38: =L37*$C$37 -> 0 | ... AC38: =AC37*$C$37 -> 0
A39: Fodder Development | B39: Million Rupees | C39: 1 | E39: 11.112 | F39: 11.112 | G39: 22.224 | H39: 11.112 | I39: 11.112 | J39: 11.112 | K39: 0 | L39: 0 | M39: 0 | N39: 0 | O39: 0 | P39: 0 | Q39: 0 | R39: 0 | S39: 0 | T39: 0 | U39: 0 | V39: 0 | W39: 0 | X39: 0 | Y39: 0 | Z39: 0 | AA39: 0 | AB39: 0 | AC39: 0
E40: =E39*$C$39 -> 11.112 | F40: =F39*$C$39 -> 11.112 | G40: =G39*$C$39 -> 22.224 | H40: =H39*$C$39 -> 11.112 | I40: =I39*$C$39 -> 11.112 | J40: =J39*$C$39 -> 11.112 | K40: =K39*$C$39 -> 0 | L40: =L39*$C$39 -> 0 | ... AC40: =AC39*$C$39 -> 0
A41: Straw Densification Plant | B41: Million Rupees | C41: 1 | E41: 0 | F41: 16.68 | G41: 38.92 | H41: 16.68 | I41: 38.92 | J41: 0 | K41: 0 | L41: 0 | M41: 0 | N41: 0 | O41: 0 | P41: 0 | Q41: 0 | R41: 0 | S41: 0 | T41: 0 | U41: 0 | V41: 0 | W41: 0 | X41: 0 | Y41: 0 | Z41: 0 | AA41: 0 | AB41: 0 | AC41: 0
E42: =$C$41*E41 -> 0 | F42: =$C$41*F41 -> 16.68 | G42: =$C$41*G41 -> 38.92 | H42: =$C$41*H41 -> 16.68 | I42: =$C$41*I41 -> 38.92 | J42: =$C$41*J41 -> 0 | K42: =$C$41*K41 -> 0 | L42: =$C$41*L41 -> 0 | ... AC42: =$C$41*AC41 -> 0
A43: Animal Health care | B43: Million Rupees | C43: 1 | E43: 0 | F43: 0 | G43: 0 | H43: 0 | I43: 0 | J43: 0 | K43: 0 | L43: 0
E44: =E43*$C$43 -> 0 | F44: =F43*$C$43 -> 0 | G44: =G43*$C$43 -> 0 | H44: =H43*$C$43 -> 0 | I44: =I43*$C$43 -> 0 | J44: =J43*$C$43 -> 0 | K44: =K43*$C$43 -> 0 | L44: =L43*$C$43 -> 0 | ... AC44: =AC43*$C$43 -> 0
...

Sheet Comp B-BMC
A1: Details of savings in cost to Union/Dairy plant due to use of BMC's vis a vis Cans for milk collection | G1: Benefits to DCS by installing BMCU
A2: Sr No. | B2: Details / particulas of savings | C2: Range of saving in cost in Rs per lt of milk * | E2: Saving | G2: Sr No. | H2: Details / particulas of savings | I2: Range of saving in cost in Rs per lt of milk * | K2: Saving
C3: Min | D3: Max | I3: Min | J3: Max
A4: 1 | B4: Transportation Cost ^^ : There is saving in cost of raw milk transporation to dairy in case BMC's are installed. The cost of transportation varies based on number of factors such as density of milk procurement , route length etc . The details are worked based on data conveyed by the different dairy plants . | C4: 0.15 | D4: 0.205 | E4: 0.15 | G4: 1 | H4: Elimination of variation in quantity,fat and SNF. As informed , the average savings comes to approx 0.105% ^^of FAT and 0.09 % ^^of SNF. Considering rate of milk as Rs 18.00 to 20.00 per Kg , the saving is | I4: 0.32 | J4: 0.36 | K4: =I4 -> 0.32
A5: 2 | B5: Due to elimination of need for refrigeration / can cleaning/ sterilization with steam . The saving due to elimination of chilling comes to approx Rs 0.10-0.17 per liltre of milk and due to elimination of steam/ can operation in can washer comes to approx Rs 0.02 to 0.03 paise per litre of milk. | C5: 0.15 | D5: 0.18 | E5: =C5 -> 0.15 | G5: 2 | H5: Elimination of sourage / curdling of milk supplied to dairy plant. Considering sourage/ curdling of approx 1.5 % ^^of milk ( as reported by study conducted by Center for Management Development, Trivandrum) and rate of Rs 18.00 to Rs 20.00 per Kg of milk, the saving is | I5: =1.5*14/100 -> 0.21 | J5: =18*1.5/100 -> 0.27 | K5: =I5 -> 0.21
A6: 3 | B6: Due to reduction in labour charges for handling cans and tankers at dairy plant. Considering minimum volume of 10,000 lpd, the can reception ( for 2 shifts) shall need 6 handling persons @ Rs 100 per person ( Rs 0.06 per lt ). In case of handlin tankers , only 2 handling persons ae needed. So the saving is approx rs 0.04 per litre of milk handled. | C6: 0.04 | D6: 0.04 | E6: =C6 -> 0.04 | G6: 3 | H6: Due to reduction in manpower for handling cans . Saving of 1 person per DCS @Rs 100 per day per peson for handling approx 2000 lts to 2400 lts of milk per day | I6: =100/2400 -> 0.041666667 | J6: =100/2000 -> 0.05 | K6: =I6 -> 0.041666667
A7: 4 | B7: Elimination of cost related to replacement/ damage to the cans. The life of cans is taken as 7 years and cost of repairs is approx Rs 2500 in 7 years. | C7: 0.02 | D7: 0.03 | E7: 0 | G7: 4 | H7: Due to receipt of Quality Incentive from Union for good quality of milk . Generally it is (minimum)@ Rs3 to 5 per Kg fat for average 5-6% fat | I7: =(5/100)*3 -> 0.15 | J7: =(6/100)*5 -> 0.3 | K7: 0
A8: 5 | B8: Due to need for keeping lower pasteurisation temp in case of receipt of milk through BMC's and cans . Difference of approx 2 to 3 deg C | C8: 0.05 | D8: 0.06 | E8: =C8 -> 0.05 | H8: Total | I8: =SUM(I4:I7) -> 0.72166667 | J8: =SUM(J4:J7) -> 0.98 | K8: =SUM(K4:K7) -> 0.57166667
B9: TOTAL | C9: =SUM(C4:C8) -> 0.41 | D9: =SUM(D4:D8) -> 0.515 | E9: =SUM(E4:E8) -> 0.39 | H9: Note: In addition to the above , the DCS gets paid from Union for cooling and BMC cleaning charges approx @ Rs 0.18 to Rs 0.20 per lt of milk. | K9: 0.2
B10: Note : *The range is taken on lower scale. | G10: The Union would pay Re .20/ltire to the DCS for the milk handled as savings from the non-operation of chilling centre
B11: ^^ Report on evaluation (2003-04 to 2007-08) prepared by Centre for Management Development, Trivandrum to study the scheme "Stregthening Infrastructure for Quality and Clean Milk Production" implemented by Dept of AHDF, Govt of India
B12: Other benefits : - | R12: Economic Benefit Calculation | T12: Economic
B13: 1. Increase in handling capacity of plant as no restriction on milk receipt time ( morning and evening). | H13: Net Cost savings | T13: Cost | U13: Factor
B14: 2. In case of supply of bulk mik to other nearby unions ( up to 250 kms), in case BMC's are installed then the milk can be transported directly to other union without bringing to dairy for pasteurisation / chilling ( thus saving in cost). | Q14: 0.6 | R14: Transport Fuel Cost | T14: 0.063 | U14: 0.7
B15: 3. Due to good quality of milk without dust / extraneous matter, performance of pasteurisers and separators is better and maintenance cost goes down | F15: Transportation | J15: 0.15 | K15: 0.19693654 | Q15: 0.6 | R15: Power savings due to elimination of chilling and steam sterilization | T15: 0.36 | U15: 4
B16: 4. Marked improvement in quality of market liquid milk and products such as powder, paneer, dahi etc. | F16: Opearations | J16: 0.32 | K16: 0.42013129 | Q16: 1 | R16: Cost savings due to elimination of cans | T16: 0
B17: 5. Adulteration of milk and spillage from cans during transport can be eliminated | F17: Handling | J17: 0.081666667 | K17: 0.10722101 | Q17: 1 | R17: Power savings due to lower pasteurization temp (by 2-3 degrees) needs | T17: 0.2 | U17: 4
B18: 6.This offers a risk free working enivronment in dairies and innumerable options for value addition | F18: Processing | J18: 0.21 | K18: 0.27571116 | Q18: 0.5 | R18: Reduced variation in SNF and Fat | T18: 0.16170876 | U18: 1.0106797
B19: 7. Saving of initial investment on purchase of cans | Q19: 1 | R19: Elimination of sourage and curdling of milk | T19: 0.21224274 | U19: 1.0106797
H20: 2007/08 prices | J20: =SUM(J15:J19) -> 0.76166667 | T20: =+SUM(T14:T19) -> 0.9969515
Q21: Ratio of Economic to Financial Price
I22: 1.2483721
H23: 2010/11 prices | J23: =+J20*$I$22 -> 0.95084341 | Q23: =+Q25 -> 1.3089079 | T23: =+T20*I22 -> 1.2445664
Q25: =+T23/J23 -> 1.3089079

Sheet Feed and Fodder
A1: Sr. No. | B1: Study | C1: Authors | D1: Source | E1: Year of Publication | F1: Area of Study | G1: Sample size | H1: Breed of Buffalos and Cows | I1: Current Yield | J1: No. of farmers considered | K1: Type of farmers | L1: IMPACT Indicators | M1: Without | N1: With | Q1: Increase/Decrease | T1: Benefits Addressed | U1: Remarks
A3: 1 | B3: Assesment of Economic Impact of Implementing RBP in Lactating Cows and Buffaloes under field conditions | C3: MR Garg, S A Biradar and A Kannan | D3: Indian Journal of Animal Nutrition | E3: 2009 | F3: Junagadh in Gujarat | G3: Lactating Animals : 2536 Buffloes : 1709 Cows :827 | H3: Buffaloes : Jaffrabadi Cows : Gir | I3: 6-12 kg/day | J3: 1250 | K3: Marginal (<1 hectare) | L3: Average Milk Yield/Day | M3: 8.25 | N3: 8.83 | Q3: =N3-M3 -> 0.58 | S3: 0.5 | T3: 1. Increase in milk productivity 2. Improved milk quality (milk solids) 3.Minimized unit cost of production 4. Opportunity cost of saved fodder can be calculated | U3: Lactation trial of 120 days duration was conducted on 2536 lactating animals in 25 villages in Junagadh District in Guajrat
L4: Average fat content(%) | M4: 5.79 | N4: 6.29 | Q4: =N4-M4 -> 0.5 | S4: 0.0025
L5: Daily Feeding Cost/kg Milk Production | M5: =9.45 -> 9.45 | N5: 7.47 | Q5: =M5-N5 -> 1.98 | R5: =Q5/M5 -> 0.20952381
S6: =R5*0.9 -> 0.18857143 | U6: 90 % of the total percentage of reduction of daily feeding costs considered ( cosnervatism)
A7: 2 | B7: Effect of RBP on Methane Emission Reductions in Lactating Animals Under Field Conditions | C7: A Kannan and M R Garg | D7: Indian Journal of Dairy Sciences | E7: 2009 | F7: Junagadh district in Gujarat | G7: Buffloes : 22 Cows :5 | H7: Buffaloes : Jaffrabadi Cows : Gir | I7: Buffalo : 3rd-5th lactation. Prodn; 8-12 kg milk;6-7.5%fat , Cows : 4th -6th Lactation, Prodn: 9.5-12.5 kg, 4-4.5%fat | J7: 10 | K7: -- | L7: Energy Loss as methane (% of gross energy) - Buffalo | M7: 5.64 | N7: 4.9 | Q7: =5.64-4.9 -> 0.74 | T7: Reduction in methane emissions due to RBP | U7: Baseline emissions of alll the animals were estimated using Sulphur Hexaflouride techinque and then ration was balanced as per their nutrient requirement.
L8: Energy Loss as methane (% of gross energy)- Cows | M8: 5.85 | N8: 5.14 | Q8: =5.85-5.14 -> 0.71
L9: Methane Emission in buffaloes (g/animal/day) | M9: 232.48 | N9: 199.6 | Q9: =M9-N9 -> 32.88 | R9: =Q9/M9*100 -> 14.143152 | U9: Total Reduction in Methane emissions in buffaloes and cows are 14.14% and 13.29% respectively but for our calculations we are taking conservative estimates of 10% reduction
M10: 237.74 | N10: 206.13 | Q10: =M10-N10 -> 31.61 | R10: =Q10/M10*100 -> 13.296038
A11: 3 | B11: Effect of Ration Balancing on Methane Emission and Milk Production in Lactating Animals under Field Conditions in Raebareli District of Uttar Pradesh | C11: A Kannan, M.R. Garg and Pankaj Singh | D11: Indian Journal of Animal Nutrition | E11: 2010 | F11: Raebareli District of Uttar Pradesh | G11: Buffaloes : 13 Cows : 13 | I11: Buffalo : 2nd-4th lactation. Prodn; 4-6.5 kg milk; 5.0-6.5%fat , Cows : 3rd -4th Lactation, Prodn: 4.0-6.5 kg, 3.5-5.0%fat | J11: 20 | K11: -- | L11: Energy Loss as methane (% of gross energy) - Buffalo | M11: 6.48 | N11: 5.78 | Q11: =5.64-4.9 -> 0.74 | T11: Reduction in methane emissions due to RBP | U11: Total reduction in Methane emission in buffaloes and cows is 10.48 and 11.37%, respectively. For our calculations we have taken a conservative estimate of 10% methane emission reduction due to RBP.
L12: Energy Loss as methane (% of gross energy)- Cows | M12: 6.46 | N12: 5.55
L13: Milk yield (Kg/day) : Buffaloes | M13: 5.25 | N13: 5.93 | Q13: =N13-M13 -> 0.68
L14: Milk yield (Kg/day) : Cows | M14: 4.95 | N14: 5.5 | Q14: =N14-M14 -> 0.55 | S14: =0.5 -> 0.5
L15: Milk fat (%) : Buffaloes | M15: 5.98 | N15: 6.32 | Q15: =N15-M15 -> 0.34 | S15: =AVERAGE(Q15,Q16) -> 0.265
L16: Milf fat (%) : Cows | M16: 4.2 | N16: 4.39 | Q16: =N16-M16 -> 0.19
L17: Methane Emission in buffaloes (g/animal/day) | M17: 214.68 | N17: 192.19 | R17: 0.1048
L18: Methane Emission in cows (g/animal/day) | M18: 195.79 | N18: 173.54 | R18: 0.1137
M19: =+AVERAGE(M9,M17) -> 223.58
B22: Type | C22: Proportion of Animals | D22: Methane Emissions Kg/animal/annum | G22: References
B23: Indigenous | C23: 0.2 | D23: 28 | G23: NATCOM, 2004: India's Initial National Communication to UNFCCC, Ministry of Enviornment & Forests, Government of India.
B24: Cross Bred | C24: 0.5 | D24: =195.79*365/1000 -> 71.46335 | E24: (@195.79g/animal/day) | G24: Kannan,A., Garg,MR and Pankaj Singh.2010. Effect of Ration Balancing on Methane Emission and Milk Production in Lactating Animals under Field Conditions in Rae Bareli district of Uttar Pradesh . Indian journal of Animal Nutrition.27(2):103-108
B25: Bufflaoes | C25: 0.3 | D25: =223.58*365/1000 -> 81.6067 | E25: (@223.58 g/animal/day) | G25: Kannan,A. and Garg M R 2009. Effect of RBP on Methane Emission Reductions in Lactating Animals Under Field Conditions. Indian Journal of Dairy Science 62(4)292-296. Kannan,A., Garg,MR and Pankaj Singh.2010. Effect of Ration Balancing on Methane Emission and Milk Production in Lactating Animals under Field Conditions in Rae Bareli district of Uttar Pradesh . Indian journal of Animal Nutrition.27(2):103-108
B27: Average/Animal Per annum (Methane emission) | C27: kg/animal/year | D27: =(D23*C23)+(D24*C24)+(D25*C25) -> 65.813685 | E27: =+D27*C32 -> 1645.3421
B30: Reduction of methane emissions by 10% | C30: 0.1 | D30: =D27*C30 -> 6.5813685 | E30: Garg et al. (2009); Kannan and Garg (2009); Kannan et al. (2010)
B32: Carbon di-oxide equivalent ( 1 Kg of Methane = 25 Kg of CO2) | C32: 25 | D32: =D30*C32 -> 164.53421 | E32: Website of IPCC, 2007. Climate Change 2007. The Physical Science Basis. Intergovernmental Panel on Climate Change.
B33: Certified Emission Reductions (CER) | C33: Tonnes/Animal/Annum | D33: =D32/1000 -> 0.16453421
B34: Benefit per animal per annum @ Rs. 740 per CER (Rs.) | C34: 740 | D34: =D33*C34 -> 121.75532 | E34: Spot carbon credit price taken from National Commodity & Derivatives Exchange Limited of India, 2010
D38: =+D33*'Feed and Fodder (F) Zone.1'!S6/1000000 -> 0.44740143
H40: =F40*G40 -> 0
H41: =F41*G41 -> 0

Sheet Feed and Fodder (F) Zone.1
A1: Contribution of Feed & Nutrition to Additional Milk Production
C2: Current | E2: 2011-12 | F2: 2012-13 | G2: 2013-14 | H2: 2014-15 | I2: 2015-16 | J2: 2016-17 | K2: 2017-18 | L2: 2018-19 | M2: 2019-20 | N2: 2020-21 | O2: 2021-22 | P2: 2022-23 | Q2: 2023-24 | R2: 2024-25 | S2: 2025-26 | T2: 2026-27 | U2: 2027-28 | V2: 2028-29 | W2: 2029-30 | X2: 2030-31 | Y2: 2031-32 | Z2: 2032-33 | AA2: 2033-34 | AB2: 2034-35 | AC2: 2036-37
A3: A. | B3: Ration Balancing Programme RBP
B4: PDAs (Nos.) | C4: 25 | E4: 830 | F4: 1270 | G4: 730 | H4: 730 | I4: 1630 | J4: 2010 | K4: =J4 -> 2010 | L4: =K4 -> 2010 | M4: =L4 -> 2010 | N4: =M4 -> 2010 | O4: =N4 -> 2010 | P4: =O4 -> 2010 | Q4: =P4 -> 2010 | R4: =Q4 -> 2010 | S4: =R4 -> 2010
B5: Villages (Nos) | E5: 5500 | F5: 11100 | G5: 17700 | H5: 27300 | I5: 35880 | J5: 40320 | K5: 40320 | L5: 40320 | M5: 40320 | N5: 40320 | O5: 40320 | P5: 40320 | Q5: 40320 | R5: 40320 | S5: 40320 | T5: 40320 | U5: 40320 | V5: 40320 | W5: 40320 | X5: 40320 | Y5: 40320 | Z5: 40320 | AA5: 40320 | AB5: 40320 | AC5: 40320
B6: Animals covered (Nos) | E6: 366000 | F6: 741000 | G6: 1188000 | H6: 1818000 | I6: 2392800 | J6: 2719200 | K6: 2719200 | L6: 2719200 | M6: 2719200 | N6: 2719200 | O6: 2719200 | P6: 2719200 | Q6: 2719200 | R6: 2719200 | S6: 2719200 | T6: 2719200 | U6: 2719200 | V6: 2719200 | W6: 2719200 | X6: 2719200 | Y6: 2719200 | Z6: 2719200 | AA6: 2719200 | AB6: 2719200 | AC6: 2719200
B7: Average increase in milk production due to the programme (KgPD/Animal) | E7: ='Feed and Fodder'!S14 -> 0.5 | F7: =E7 -> 0.5 | G7: =F7 -> 0.5 | H7: =G7 -> 0.5 | I7: =H7 -> 0.5 | J7: =I7 -> 0.5 | K7: =J7 -> 0.5 | L7: =K7 -> 0.5 | M7: =L7 -> 0.5 | ... AC7: =AB7 -> 0.5
B8: Net increase in milk production in the year (million MT*) | E8: =E6*E7*365/1000000000 -> 0.066795 | F8: =F6*F7*365/1000000000 -> 0.1352325 | G8: =G6*G7*365/1000000000 -> 0.21681 | H8: =H6*H7*365/1000000000 -> 0.331785 | I8: =I6*I7*365/1000000000 -> 0.436686 | J8: =J6*J7*365/1000000000 -> 0.496254 | K8: =K6*K7*365/1000000000 -> 0.496254 | L8: =L6*L7*365/1000000000 -> 0.496254 | ... AC8: =AC6*AC7*365/1000000000 -> 0.496254
A10: B | B10: Fodder Seed
B11: Fodder Seed Plants (Nos) | E11: 1 | F11: 2 | G11: 4 | H11: 5 | I11: 6 | J11: 7 | K11: =J11 -> 7 | L11: =K11 -> 7 | M11: =L11 -> 7 | N11: =M11 -> 7 | O11: =N11 -> 7 | P11: =O11 -> 7 | Q11: =P11 -> 7 | R11: =Q11 -> 7 | ... AC11: =AB11 -> 7
B12: Capacity of Fodder Seed Plants (MTD) | E12: 10 | F12: 10 | G12: 10 | H12: 10 | I12: 10 | J12: 10 | K12: 10 | L12: 10 | M12: 10 | N12: 10 | O12: 10 | P12: 10 | Q12: 10 | R12: 10 | S12: 10 | T12: =S12 -> 10 | U12: =T12 -> 10 | V12: =U12 -> 10 | W12: =V12 -> 10 | X12: =W12 -> 10 | Y12: =X12 -> 10 | Z12: =Y12 -> 10 | AA12: =Z12 -> 10 | ... AC12: =AB12 -> 10
B13: Anticipated annual Fodder Seed Production (MT) | E13: 300 | F13: 600 | G13: 1200 | H13: 1500 | I13: 1800 | J13: 2100 | K13: =J13 -> 2100 | L13: =K13 -> 2100 | M13: =L13 -> 2100 | N13: =M13 -> 2100 | O13: =N13 -> 2100 | P13: =O13 -> 2100 | Q13: =P13 -> 2100 | R13: =Q13 -> 2100 | ... AC13: =AB13 -> 2100
B14: Fodder seed required per hactare (Kg) | E14: 50 | F14: 50 | G14: 50 | H14: 50 | I14: 50 | J14: 50 | K14: 50 | L14: 50 | M14: 50 | N14: 50 | O14: 50 | P14: 50 | Q14: 50 | R14: 50 | S14: 50 | T14: =S14 -> 50 | U14: =T14 -> 50 | V14: =U14 -> 50 | W14: =V14 -> 50 | X14: =W14 -> 50 | Y14: =X14 -> 50 | Z14: =Y14 -> 50 | AA14: =Z14 -> 50 | ... AC14: =AB14 -> 50
B15: Total area under fodder seed production (ha) | E15: =E13*1000/E14 -> 6000 | F15: =F13*1000/F14 -> 12000 | G15: =G13*1000/G14 -> 24000 | H15: =H13*1000/H14 -> 30000 | I15: =I13*1000/I14 -> 36000 | J15: =J13*1000/J14 -> 42000 | K15: =K13*1000/K14 -> 42000 | L15: =L13*1000/L14 -> 42000 | ... S15: =S13*1000/S14 -> 42000 | T15: =S15 -> 42000 | U15: =T15 -> 42000 | V15: =U15 -> 42000 | W15: =V15 -> 42000 | X15: =W15 -> 42000 | Y15: =X15 -> 42000 | Z15: =Y15 -> 42000 | AA15: =Z15 -> 42000 | ... AC15: =AB15 -> 42000
B16: Increase in fodder production per hactare (MT) | E16: 40 | F16: 40 | G16: 40 | H16: 40 | I16: 40 | J16: 40 | K16: 40 | L16: 40 | M16: 40 | N16: 40 | O16: 40 | P16: 40 | Q16: 40 | R16: 40 | S16: 40 | T16: =S16 -> 40 | U16: =T16 -> 40 | V16: =U16 -> 40 | W16: =V16 -> 40 | X16: =W16 -> 40 | Y16: =X16 -> 40 | Z16: =Y16 -> 40 | AA16: =Z16 -> 40 | ... AC16: =AB16 -> 40
B17: Annual increase in fodder production (million MT) | E17: =E15*E16/1000000 -> 0.24 | F17: =F15*F16/1000000 -> 0.48 | G17: =G15*G16/1000000 -> 0.96 | H17: =H15*H16/1000000 -> 1.2 | I17: =I15*I16/1000000 -> 1.44 | J17: =J15*J16/1000000 -> 1.68 | K17: =K15*K16/1000000 -> 1.68 | L17: =L15*L16/1000000 -> 1.68 | ... S17: =S15*S16/1000000 -> 1.68 | T17: =S17 -> 1.68 | U17: =T17 -> 1.68 | V17: =U17 -> 1.68 | W17: =V17 -> 1.68 | X17: =W17 -> 1.68 | Y17: =X17 -> 1.68 | Z17: =Y17 -> 1.68 | AA17: =Z17 -> 1.68 | ... AC17: =AB17 -> 1.68
B18: Increase in milk production for every 10 Kg fodder (Kg) | E18: 1 | F18: 1 | G18: 1 | H18: 1 | I18: 1 | J18: 1 | K18: 1 | L18: 1 | M18: 1 | N18: 1 | O18: 1 | P18: 1 | Q18: 1 | R18: 1 | S18: 1 | T18: =S18 -> 1 | U18: =T18 -> 1 | V18: =U18 -> 1 | W18: =V18 -> 1 | X18: =W18 -> 1 | Y18: =X18 -> 1 | Z18: =Y18 -> 1 | AA18: =Z18 -> 1 | ... AC18: =AB18 -> 1
B19: Net increase in milk production in the year (million MT) | E19: =E17*E18/10 -> 0.024 | F19: =F17*F18/10 -> 0.048 | G19: =G17*G18/10 -> 0.096 | H19: =H17*H18/10 -> 0.12 | I19: =I17*I18/10 -> 0.144 | J19: =J17*J18/10 -> 0.168 | K19: =K17*K18/10 -> 0.168 | L19: =L17*L18/10 -> 0.168 | ... S19: =S17*S18/10 -> 0.168 | T19: =S19 -> 0.168 | U19: =T19 -> 0.168 | V19: =U19 -> 0.168 | W19: =V19 -> 0.168 | X19: =W19 -> 0.168 | Y19: =X19 -> 0.168 | Z19: =Y19 -> 0.168 | AA19: =Z19 -> 0.168 | ... AC19: =AB19 -> 0.168
B20: Net increase in milk production in the year ('000 Tonnes) | E20: =E19*1000 -> 24 | F20: =F19*1000 -> 48 | G20: =G19*1000 -> 96 | H20: =H19*1000 -> 120 | I20: =I19*1000 -> 144 | J20: =J19*1000 -> 168 | K20: =K19*1000 -> 168 | L20: =L19*1000 -> 168 | ... S20: =S19*1000 -> 168 | T20: =S20 -> 168 | U20: =T20 -> 168 | V20: =U20 -> 168 | W20: =V20 -> 168 | X20: =W20 -> 168 | Y20: =X20 -> 168 | Z20: =Y20 -> 168 | AA20: =Z20 -> 168 | ... AC20: =AB20 -> 168
A22: C | B22: Straw Densification Plants ( Nos.) | E22: 0 | F22: 1 | G22: 1 | H22: 2 | I22: 2 | J22: 2 | K22: =J22 -> 2 | L22: =K22 -> 2 | M22: =L22 -> 2 | N22: =M22 -> 2 | O22: =N22 -> 2 | P22: =O22 -> 2 | Q22: =P22 -> 2 | R22: =Q22 -> 2 | ... AC22: =AB22 -> 2
B23: Capacity of Straw Densification Plants (MTD) | E23: 40 | F23: 40 | G23: 40 | H23: 40 | I23: 40 | J23: 40 | K23: 40 | L23: 40 | M23: 40 | N23: 40 | O23: 40 | P23: 40 | Q23: 40 | R23: 40 | S23: 40 | T23: 40 | U23: 40 | V23: 40 | W23: 40 | X23: 40 | Y23: 40 | Z23: 40 | AA23: 40 | AB23: 40 | AC23: 40
B24: Anticipated Annual Production (MT) | E24: =E22*E23*300 -> 0 | F24: =F22*F23*300 -> 12000 | G24: =G22*G23*300 -> 12000 | H24: =H22*H23*300 -> 24000 | I24: =I22*I23*300 -> 24000 | J24: =J22*J23*300 -> 24000 | K24: =K22*K23*300 -> 24000 | L24: =L22*L23*300 -> 24000 | ... AC24: =AC22*AC23*300 -> 24000
A25: C | B25: Devt of permanent pasture & common grazing lands
B26: Live Fencing, Plantation, Perennial Grass Seeding, Land and Irrigation Development (Area to be covered) | E26: 400 | F26: 800 | G26: 1200 | H26: 1600 | I26: 2000 | J26: 2800 | K26: =J26 -> 2800 | L26: =K26 -> 2800 | M26: =L26 -> 2800 | N26: =M26 -> 2800 | O26: =N26 -> 2800 | P26: =O26 -> 2800 | Q26: =P26 -> 2800 | R26: =Q26 -> 2800 | ... AC26: =AB26 -> 2800
B27: Incremental Biomass (From 0.75 MT/ hect/yr to 5.75 MT/hect/yr) | E27: =E26*5 -> 2000 | F27: =F26*5 -> 4000 | G27: =G26*5 -> 6000 | H27: =H26*5 -> 8000 | I27: =I26*5 -> 10000 | J27: =J26*5 -> 14000 | K27: =J27 -> 14000 | L27: =K27 -> 14000 | M27: =L27 -> 14000 | N27: =M27 -> 14000 | O27: =N27 -> 14000 | P27: =O27 -> 14000 | Q27: =P27 -> 14000 | R27: =Q27 -> 14000 | ... AC27: =AB27 -> 14000
B28: Annual increase in fodder production (million MT) | E28: =E27/1000000 -> 0.002 | F28: =F27/1000000 -> 0.004 | G28: =G27/1000000 -> 0.006 | H28: =H27/1000000 -> 0.008 | I28: =I27/1000000 -> 0.01 | J28: =J27/1000000 -> 0.014 | K28: =J28 -> 0.014 | L28: =K28 -> 0.014 | M28: =L28 -> 0.014 | N28: =M28 -> 0.014 | O28: =N28 -> 0.014 | P28: =O28 -> 0.014 | Q28: =P28 -> 0.014 | R28: =Q28 -> 0.014 | ... AC28: =AB28 -> 0.014
B29: Increase in milk production for every 10 Kg fodder (Kg) | E29: 1 | F29: 1 | G29: 1 | H29: 1 | I29: 1 | J29: 1 | K29: =J29 -> 1 | L29: =K29 -> 1 | M29: =L29 -> 1 | N29: =M29 -> 1 | O29: =N29 -> 1 | P29: =O29 -> 1 | Q29: =P29 -> 1 | R29: =Q29 -> 1 | ... AC29: =AB29 -> 1
B30: Net increase in milk production in the year (million MT) | E30: =E28*E29/10 -> 0.0002 | F30: =F28*F29/10 -> 0.0004 | G30: =G28*G29/10 -> 0.0006 | H30: =H28*H29/10 -> 0.0008 | I30: =I28*I29/10 -> 0.001 | J30: =J28*J29/10 -> 0.0014 | K30: =J30 -> 0.0014 | L30: =K30 -> 0.0014 | M30: =L30 -> 0.0014 | N30: =M30 -> 0.0014 | O30: =N30 -> 0.0014 | P30: =O30 -> 0.0014 | Q30: =P30 -> 0.0014 | R30: =Q30 -> 0.0014 | ... AC30: =AB30 -> 0.0014
B31: Net increase in milk production in the year ('000 Tonnes) | E31: =E30*1000 -> 0.2 | F31: =F30*1000 -> 0.4 | G31: =G30*1000 -> 0.6 | H31: =H30*1000 -> 0.8 | I31: =I30*1000 -> 1 | J31: =J30*1000 -> 1.4 | K31: =K30*1000 -> 1.4 | L31: =L30*1000 -> 1.4 | ... S31: =S30*1000 -> 1.4 | T31: =S31 -> 1.4 | U31: =T31 -> 1.4 | V31: =U31 -> 1.4 | W31: =V31 -> 1.4 | X31: =W31 -> 1.4 | Y31: =X31 -> 1.4 | Z31: =Y31 -> 1.4 | AA31: =Z31 -> 1.4 | ... AC31: =AB31 -> 1.4
A32: D | B32: Organising Varietal Demonstrations (1/10 of Hect) | E32: 20000 | F32: 40000 | G32: 60000 | H32: 80000 | I32: 100000 | J32: 140000 | K32: =J32 -> 140000 | L32: =K32 -> 140000 | M32: =L32 -> 140000 | N32: =M32 -> 140000 | O32: =N32 -> 140000 | P32: =O32 -> 140000 | Q32: =P32 -> 140000 | R32: =Q32 -> 140000 | ... AC32: =AB32 -> 140000
B33: Villages covered under Varietal Demonstrations (nos.) | E33: =E32/4 -> 5000 | F33: =F32/4 -> 10000 | G33: =G32/4 -> 15000 | H33: =H32/4 -> 20000 | I33: =I32/4 -> 25000 | J33: =J32/4 -> 35000 | K33: =J33 -> 35000 | L33: =K33 -> 35000 | M33: =L33 -> 35000 | N33: =M33 -> 35000 | O33: =N33 -> 35000 | P33: =O33 -> 35000 | Q33: =P33 -> 35000 | R33: =Q33 -> 35000 | ... AC33: =AB33 -> 35000
B34: Villages covered under Varietal Demonstrations (nos.) | E34: =E32/10 -> 2000 | F34: =F32/10 -> 4000 | G34: =G32/10 -> 6000 | H34: =H32/10 -> 8000 | I34: =I32/10 -> 10000 | J34: =J32/10 -> 14000 | K34: =J34 -> 14000 | L34: =K34 -> 14000 | M34: =L34 -> 14000 | N34: =M34 -> 14000 | O34: =N34 -> 14000 | P34: =O34 -> 14000 | Q34: =P34 -> 14000 | R34: =Q34 -> 14000 | ... AC34: =AB34 -> 14000
B35: Increase in fodder production per hactare (MT) | E35: 40 | F35: 40 | G35: 40 | H35: 40 | I35: 40 | J35: 40 | K35: 40 | L35: =K35 -> 40 | M35: =L35 -> 40 | N35: =M35 -> 40 | O35: =N35 -> 40 | P35: =O35 -> 40 | Q35: =P35 -> 40 | R35: =Q35 -> 40 | S35: =R35 -> 40 | ... AC35: =AB35 -> 40
B36: Annual increase in fodder production (million MT) | E36: =E34*E35/1000000 -> 0.08 | F36: =F34*F35/1000000 -> 0.16 | G36: =G34*G35/1000000 -> 0.24 | H36: =H34*H35/1000000 -> 0.32 | I36: =I34*I35/1000000 -> 0.4 | J36: =J34*J35/1000000 -> 0.56 | K36: =K34*K35/1000000 -> 0.56 | L36: =K36 -> 0.56 | M36: =L36 -> 0.56 | N36: =M36 -> 0.56 | O36: =N36 -> 0.56 | P36: =O36 -> 0.56 | Q36: =P36 -> 0.56 | R36: =Q36 -> 0.56 | S36: =R36 -> 0.56 | ... AC36: =AB36 -> 0.56
B37: Increase in milk production for every 10 Kg fodder (Kg) | E37: 1 | F37: 1 | G37: 1 | H37: 1 | I37: 1 | J37: 1 | K37: =J37 -> 1 | L37: =K37 -> 1 | M37: =L37 -> 1 | N37: =M37 -> 1 | O37: =N37 -> 1 | P37: =O37 -> 1 | Q37: =P37 -> 1 | R37: =Q37 -> 1 | ... AC37: =AB37 -> 1
B38: Net increase in milk production in the year (million MT) | E38: =E36*E37/10 -> 0.008 | F38: =F36*F37/10 -> 0.016 | G38: =G36*G37/10 -> 0.024 | H38: =H36*H37/10 -> 0.032 | I38: =I36*I37/10 -> 0.04 | J38: =J36*J37/10 -> 0.056 | K38: =J38 -> 0.056 | L38: =K38 -> 0.056 | M38: =L38 -> 0.056 | N38: =M38 -> 0.056 | O38: =N38 -> 0.056 | P38: =O38 -> 0.056 | Q38: =P38 -> 0.056 | R38: =Q38 -> 0.056 | ... AC38: =AB38 -> 0.056
B39: Net increase in milk production in the year ('000 Tonnes) | E39: =E38*1000 -> 8 | F39: =F38*1000 -> 16 | G39: =G38*1000 -> 24 | H39: =H38*1000 -> 32 | I39: =I38*1000 -> 40 | J39: =J38*1000 -> 56 | K39: =K38*1000 -> 56 | L39: =L38*1000 -> 56 | ... S39: =S38*1000 -> 56 | T39: =S39 -> 56 | U39: =T39 -> 56 | V39: =U39 -> 56 | W39: =V39 -> 56 | X39: =W39 -> 56 | Y39: =X39 -> 56 | Z39: =Y39 -> 56 | AA39: =Z39 -> 56 | ... AC39: =AB39 -> 56
B41: Weighted average milk yield, Kg/day | C41: =+C59*1.03 -> 4.6587415
B42: Milk Productivity with RBP Intervention (Kg/day/animal), Incremental | C42: =+C41*E59 -> 0.46587415
B43: Milk Poduction with RBP intervention (Million tonnes), Incremental | C43: Million Tonnes | E43: 0 | F43: =$C$42*E6*365/1000000000 -> 0.062236128 | G43: =$C$42*F6*365/1000000000 -> 0.12600265 | H43: =$C$42*G6*365/1000000000 -> 0.20201235 | I43: =$C$42*H6*365/1000000000 -> 0.30914011 | J43: =$C$42*I6*365/1000000000 -> 0.40688144 | K43: =$C$42*J6*365/1000000000 -> 0.46238382 | L43: =$C$42*K6*365/1000000000 -> 0.46238382 | M43: =$C$42*L6*365/1000000000 -> 0.46238382 | ... AC43: =$C$42*AB6*365/1000000000 -> 0.46238382
...

Sheet Feed and Fodder (F) Zone.2
A1: Contribution of Feed & Nutrition to Additional Milk Production
C2: Current | E2: 2011-12 | F2: 2012-13 | G2: 2013-14 | H2: 2014-15 | I2: 2015-16 | J2: 2016-17 | K2: 2017-18 | L2: 2018-19 | M2: 2019-20 | N2: 2020-21 | O2: 2021-22 | P2: 2022-23 | Q2: 2023-24 | R2: 2024-25 | S2: 2025-26 | T2: 2026-27 | U2: 2027-28 | V2: 2028-29 | W2: 2029-30 | X2: 2030-31 | Y2: 2031-32 | Z2: 2032-33 | AA2: 2033-34 | AB2: 2034-35 | AC2: 2036-37
A3: A. | B3: Ration Balancing Programme RBP
B4: PDAs (Nos.) | C4: 25 | E4: 830 | F4: 1270 | G4: 730 | H4: 730 | I4: 1630 | J4: 2010 | K4: =J4 -> 2010 | L4: =K4 -> 2010 | M4: =L4 -> 2010 | N4: =M4 -> 2010 | O4: =N4 -> 2010 | P4: =O4 -> 2010 | Q4: =P4 -> 2010 | R4: =Q4 -> 2010 | S4: =R4 -> 2010
B5: Villages (Nos) | E5: 5500 | F5: 11100 | G5: 17700 | H5: 27300 | I5: 35880 | J5: 40320 | K5: 40320 | L5: 40320 | M5: 40320 | N5: 40320 | O5: 40320 | P5: 40320 | Q5: 40320 | R5: 40320 | S5: 40320 | T5: 40320 | U5: 40320 | V5: 40320 | W5: 40320 | X5: 40320 | Y5: 40320 | Z5: 40320 | AA5: 40320 | AB5: 40320 | AC5: 40320
B6: Animals covered (Nos) | E6: 366000 | F6: 741000 | G6: 1188000 | H6: 1818000 | I6: 2392800 | J6: 2719200 | K6: 2719200 | L6: 2719200 | M6: 2719200 | N6: 2719200 | O6: 2719200 | P6: 2719200 | Q6: 2719200 | R6: 2719200 | S6: 2719200 | T6: 2719200 | U6: 2719200 | V6: 2719200 | W6: 2719200 | X6: 2719200 | Y6: 2719200 | Z6: 2719200 | AA6: 2719200 | AB6: 2719200 | AC6: 2719200
B7: Average increase in milk production due to the programme (KgPD/Animal) | E7: ='Feed and Fodder'!S14 -> 0.5 | F7: =E7 -> 0.5 | G7: =F7 -> 0.5 | H7: =G7 -> 0.5 | I7: =H7 -> 0.5 | J7: =I7 -> 0.5 | K7: =J7 -> 0.5 | L7: =K7 -> 0.5 | M7: =L7 -> 0.5 | ... AC7: =AB7 -> 0.5
B8: Net increase in milk production in the year (million MT*) | E8: =E6*E7*365/1000000000 -> 0.066795 | F8: =F6*F7*365/1000000000 -> 0.1352325 | G8: =G6*G7*365/1000000000 -> 0.21681 | H8: =H6*H7*365/1000000000 -> 0.331785 | I8: =I6*I7*365/1000000000 -> 0.436686 | J8: =J6*J7*365/1000000000 -> 0.496254 | K8: =K6*K7*365/1000000000 -> 0.496254 | L8: =L6*L7*365/1000000000 -> 0.496254 | ... AC8: =AC6*AC7*365/1000000000 -> 0.496254
A10: B | B10: Fodder Seed
B11: Fodder Seed Plants (Nos) | E11: 1 | F11: 2 | G11: 4 | H11: 5 | I11: 6 | J11: 7 | K11: =J11 -> 7 | L11: =K11 -> 7 | M11: =L11 -> 7 | N11: =M11 -> 7 | O11: =N11 -> 7 | P11: =O11 -> 7 | Q11: =P11 -> 7 | R11: =Q11 -> 7 | ... AC11: =AB11 -> 7
B12: Capacity of Fodder Seed Plants (MTD) | E12: 10 | F12: 10 | G12: 10 | H12: 10 | I12: 10 | J12: 10 | K12: 10 | L12: 10 | M12: 10 | N12: 10 | O12: 10 | P12: 10 | Q12: 10 | R12: 10 | S12: 10 | T12: =S12 -> 10 | U12: =T12 -> 10 | V12: =U12 -> 10 | W12: =V12 -> 10 | X12: =W12 -> 10 | Y12: =X12 -> 10 | Z12: =Y12 -> 10 | AA12: =Z12 -> 10 | ... AC12: =AB12 -> 10
B13: Anticipated annual Fodder Seed Production (MT) | E13: 300 | F13: 600 | G13: 1200 | H13: 1500 | I13: 1800 | J13: 2100 | K13: =J13 -> 2100 | L13: =K13 -> 2100 | M13: =L13 -> 2100 | N13: =M13 -> 2100 | O13: =N13 -> 2100 | P13: =O13 -> 2100 | Q13: =P13 -> 2100 | R13: =Q13 -> 2100 | ... AC13: =AB13 -> 2100
B14: Fodder seed required per hactare (Kg) | E14: 50 | F14: 50 | G14: 50 | H14: 50 | I14: 50 | J14: 50 | K14: 50 | L14: 50 | M14: 50 | N14: 50 | O14: 50 | P14: 50 | Q14: 50 | R14: 50 | S14: 50 | T14: =S14 -> 50 | U14: =T14 -> 50 | V14: =U14 -> 50 | W14: =V14 -> 50 | X14: =W14 -> 50 | Y14: =X14 -> 50 | Z14: =Y14 -> 50 | AA14: =Z14 -> 50 | ... AC14: =AB14 -> 50
B15: Total area under fodder seed production (ha) | E15: =E13*1000/E14 -> 6000 | F15: =F13*1000/F14 -> 12000 | G15: =G13*1000/G14 -> 24000 | H15: =H13*1000/H14 -> 30000 | I15: =I13*1000/I14 -> 36000 | J15: =J13*1000/J14 -> 42000 | K15: =K13*1000/K14 -> 42000 | L15: =L13*1000/L14 -> 42000 | ... S15: =S13*1000/S14 -> 42000 | T15: =S15 -> 42000 | U15: =T15 -> 42000 | V15: =U15 -> 42000 | W15: =V15 -> 42000 | X15: =W15 -> 42000 | Y15: =X15 -> 42000 | Z15: =Y15 -> 42000 | AA15: =Z15 -> 42000 | ... AC15: =AB15 -> 42000
B16: Increase in fodder production per hactare (MT) | E16: 40 | F16: 40 | G16: 40 | H16: 40 | I16: 40 | J16: 40 | K16: 40 | L16: 40 | M16: 40 | N16: 40 | O16: 40 | P16: 40 | Q16: 40 | R16: 40 | S16: 40 | T16: =S16 -> 40 | U16: =T16 -> 40 | V16: =U16 -> 40 | W16: =V16 -> 40 | X16: =W16 -> 40 | Y16: =X16 -> 40 | Z16: =Y16 -> 40 | AA16: =Z16 -> 40 | ... AC16: =AB16 -> 40
B17: Annual increase in fodder production (million MT) | E17: =E15*E16/1000000 -> 0.24 | F17: =F15*F16/1000000 -> 0.48 | G17: =G15*G16/1000000 -> 0.96 | H17: =H15*H16/1000000 -> 1.2 | I17: =I15*I16/1000000 -> 1.44 | J17: =J15*J16/1000000 -> 1.68 | K17: =K15*K16/1000000 -> 1.68 | L17: =L15*L16/1000000 -> 1.68 | ... S17: =S15*S16/1000000 -> 1.68 | T17: =S17 -> 1.68 | U17: =T17 -> 1.68 | V17: =U17 -> 1.68 | W17: =V17 -> 1.68 | X17: =W17 -> 1.68 | Y17: =X17 -> 1.68 | Z17: =Y17 -> 1.68 | AA17: =Z17 -> 1.68 | ... AC17: =AB17 -> 1.68
B18: Increase in milk production for every 10 Kg fodder (Kg) | E18: 1 | F18: 1 | G18: 1 | H18: 1 | I18: 1 | J18: 1 | K18: 1 | L18: 1 | M18: 1 | N18: 1 | O18: 1 | P18: 1 | Q18: 1 | R18: 1 | S18: 1 | T18: =S18 -> 1 | U18: =T18 -> 1 | V18: =U18 -> 1 | W18: =V18 -> 1 | X18: =W18 -> 1 | Y18: =X18 -> 1 | Z18: =Y18 -> 1 | AA18: =Z18 -> 1 | ... AC18: =AB18 -> 1
B19: Net increase in milk production in the year (million MT) | E19: =E17*E18/10 -> 0.024 | F19: =F17*F18/10 -> 0.048 | G19: =G17*G18/10 -> 0.096 | H19: =H17*H18/10 -> 0.12 | I19: =I17*I18/10 -> 0.144 | J19: =J17*J18/10 -> 0.168 | K19: =K17*K18/10 -> 0.168 | L19: =L17*L18/10 -> 0.168 | ... S19: =S17*S18/10 -> 0.168 | T19: =S19 -> 0.168 | U19: =T19 -> 0.168 | V19: =U19 -> 0.168 | W19: =V19 -> 0.168 | X19: =W19 -> 0.168 | Y19: =X19 -> 0.168 | Z19: =Y19 -> 0.168 | AA19: =Z19 -> 0.168 | ... AC19: =AB19 -> 0.168
B20: Net increase in milk production in the year ('000 Tonnes) | E20: =E19*1000 -> 24 | F20: =F19*1000 -> 48 | G20: =G19*1000 -> 96 | H20: =H19*1000 -> 120 | I20: =I19*1000 -> 144 | J20: =J19*1000 -> 168 | K20: =K19*1000 -> 168 | L20: =L19*1000 -> 168 | ... S20: =S19*1000 -> 168 | T20: =S20 -> 168 | U20: =T20 -> 168 | V20: =U20 -> 168 | W20: =V20 -> 168 | X20: =W20 -> 168 | Y20: =X20 -> 168 | Z20: =Y20 -> 168 | AA20: =Z20 -> 168 | ... AC20: =AB20 -> 168
A22: C | B22: Straw Densification Plants ( Nos.) | E22: 0 | F22: 1 | G22: 1 | H22: 2 | I22: 2 | J22: 2 | K22: =J22 -> 2 | L22: =K22 -> 2 | M22: =L22 -> 2 | N22: =M22 -> 2 | O22: =N22 -> 2 | P22: =O22 -> 2 | Q22: =P22 -> 2 | R22: =Q22 -> 2 | ... AC22: =AB22 -> 2
B23: Capacity of Straw Densification Plants (MTD) | E23: 40 | F23: 40 | G23: 40 | H23: 40 | I23: 40 | J23: 40 | K23: 40 | L23: 40 | M23: 40 | N23: 40 | O23: 40 | P23: 40 | Q23: 40 | R23: 40 | S23: 40 | T23: 40 | U23: 40 | V23: 40 | W23: 40 | X23: 40 | Y23: 40 | Z23: 40 | AA23: 40 | AB23: 40 | AC23: 40
B24: Anticipated Annual Production (MT) | E24: =E22*E23*300 -> 0 | F24: =F22*F23*300 -> 12000 | G24: =G22*G23*300 -> 12000 | H24: =H22*H23*300 -> 24000 | I24: =I22*I23*300 -> 24000 | J24: =J22*J23*300 -> 24000 | K24: =K22*K23*300 -> 24000 | L24: =L22*L23*300 -> 24000 | ... AC24: =AC22*AC23*300 -> 24000
A25: C | B25: Devt of permanent pasture & common grazing lands
B26: Live Fencing, Plantation, Perennial Grass Seeding, Land and Irrigation Development (Area to be covered) | E26: 400 | F26: 800 | G26: 1200 | H26: 1600 | I26: 2000 | J26: 2800 | K26: =J26 -> 2800 | L26: =K26 -> 2800 | M26: =L26 -> 2800 | N26: =M26 -> 2800 | O26: =N26 -> 2800 | P26: =O26 -> 2800 | Q26: =P26 -> 2800 | R26: =Q26 -> 2800 | ... AC26: =AB26 -> 2800
B27: Incremental Biomass (From 0.75 MT/ hect/yr to 5.75 MT/hect/yr) | E27: =E26*5 -> 2000 | F27: =F26*5 -> 4000 | G27: =G26*5 -> 6000 | H27: =H26*5 -> 8000 | I27: =I26*5 -> 10000 | J27: =J26*5 -> 14000 | K27: =J27 -> 14000 | L27: =K27 -> 14000 | M27: =L27 -> 14000 | N27: =M27 -> 14000 | O27: =N27 -> 14000 | P27: =O27 -> 14000 | Q27: =P27 -> 14000 | R27: =Q27 -> 14000 | ... AC27: =AB27 -> 14000
B28: Annual increase in fodder production (million MT) | E28: =E27/1000000 -> 0.002 | F28: =F27/1000000 -> 0.004 | G28: =G27/1000000 -> 0.006 | H28: =H27/1000000 -> 0.008 | I28: =I27/1000000 -> 0.01 | J28: =J27/1000000 -> 0.014 | K28: =J28 -> 0.014 | L28: =K28 -> 0.014 | M28: =L28 -> 0.014 | N28: =M28 -> 0.014 | O28: =N28 -> 0.014 | P28: =O28 -> 0.014 | Q28: =P28 -> 0.014 | R28: =Q28 -> 0.014 | ... AC28: =AB28 -> 0.014
B29: Increase in milk production for every 10 Kg fodder (Kg) | E29: 1 | F29: 1 | G29: 1 | H29: 1 | I29: 1 | J29: 1 | K29: =J29 -> 1 | L29: =K29 -> 1 | M29: =L29 -> 1 | N29: =M29 -> 1 | O29: =N29 -> 1 | P29: =O29 -> 1 | Q29: =P29 -> 1 | R29: =Q29 -> 1 | ... AC29: =AB29 -> 1
B30: Net increase in milk production in the year (million MT) | E30: =E28*E29/10 -> 0.0002 | F30: =F28*F29/10 -> 0.0004 | G30: =G28*G29/10 -> 0.0006 | H30: =H28*H29/10 -> 0.0008 | I30: =I28*I29/10 -> 0.001 | J30: =J28*J29/10 -> 0.0014 | K30: =J30 -> 0.0014 | L30: =K30 -> 0.0014 | M30: =L30 -> 0.0014 | N30: =M30 -> 0.0014 | O30: =N30 -> 0.0014 | P30: =O30 -> 0.0014 | Q30: =P30 -> 0.0014 | R30: =Q30 -> 0.0014 | ... AC30: =AB30 -> 0.0014
B31: Net increase in milk production in the year ('000 Tonnes) | E31: =E30*1000 -> 0.2 | F31: =F30*1000 -> 0.4 | G31: =G30*1000 -> 0.6 | H31: =H30*1000 -> 0.8 | I31: =I30*1000 -> 1 | J31: =J30*1000 -> 1.4 | K31: =K30*1000 -> 1.4 | L31: =L30*1000 -> 1.4 | ... S31: =S30*1000 -> 1.4 | T31: =S31 -> 1.4 | U31: =T31 -> 1.4 | V31: =U31 -> 1.4 | W31: =V31 -> 1.4 | X31: =W31 -> 1.4 | Y31: =X31 -> 1.4 | Z31: =Y31 -> 1.4 | AA31: =Z31 -> 1.4 | ... AC31: =AB31 -> 1.4
A32: D | B32: Organising Varietal Demonstrations (1/10 of Hect) | E32: 20000 | F32: 40000 | G32: 60000 | H32: 80000 | I32: 100000 | J32: 140000 | K32: =J32 -> 140000 | L32: =K32 -> 140000 | M32: =L32 -> 140000 | N32: =M32 -> 140000 | O32: =N32 -> 140000 | P32: =O32 -> 140000 | Q32: =P32 -> 140000 | R32: =Q32 -> 140000 | ... AC32: =AB32 -> 140000
B33: Villages covered under Varietal Demonstrations (nos.) | E33: =E32/4 -> 5000 | F33: =F32/4 -> 10000 | G33: =G32/4 -> 15000 | H33: =H32/4 -> 20000 | I33: =I32/4 -> 25000 | J33: =J32/4 -> 35000 | K33: =J33 -> 35000 | L33: =K33 -> 35000 | M33: =L33 -> 35000 | N33: =M33 -> 35000 | O33: =N33 -> 35000 | P33: =O33 -> 35000 | Q33: =P33 -> 35000 | R33: =Q33 -> 35000 | ... AC33: =AB33 -> 35000
B34: Villages covered under Varietal Demonstrations (nos.) | E34: =E32/10 -> 2000 | F34: =F32/10 -> 4000 | G34: =G32/10 -> 6000 | H34: =H32/10 -> 8000 | I34: =I32/10 -> 10000 | J34: =J32/10 -> 14000 | K34: =J34 -> 14000 | L34: =K34 -> 14000 | M34: =L34 -> 14000 | N34: =M34 -> 14000 | O34: =N34 -> 14000 | P34: =O34 -> 14000 | Q34: =P34 -> 14000 | R34: =Q34 -> 14000 | ... AC34: =AB34 -> 14000
B35: Increase in fodder production per hactare (MT) | E35: 40 | F35: 40 | G35: 40 | H35: 40 | I35: 40 | J35: 40 | K35: 40 | L35: =K35 -> 40 | M35: =L35 -> 40 | N35: =M35 -> 40 | O35: =N35 -> 40 | P35: =O35 -> 40 | Q35: =P35 -> 40 | R35: =Q35 -> 40 | S35: =R35 -> 40 | ... AC35: =AB35 -> 40
B36: Annual increase in fodder production (million MT) | E36: =E34*E35/1000000 -> 0.08 | F36: =F34*F35/1000000 -> 0.16 | G36: =G34*G35/1000000 -> 0.24 | H36: =H34*H35/1000000 -> 0.32 | I36: =I34*I35/1000000 -> 0.4 | J36: =J34*J35/1000000 -> 0.56 | K36: =K34*K35/1000000 -> 0.56 | L36: =K36 -> 0.56 | M36: =L36 -> 0.56 | N36: =M36 -> 0.56 | O36: =N36 -> 0.56 | P36: =O36 -> 0.56 | Q36: =P36 -> 0.56 | R36: =Q36 -> 0.56 | S36: =R36 -> 0.56 | ... AC36: =AB36 -> 0.56
B37: Increase in milk production for every 10 Kg fodder (Kg) | E37: 1 | F37: 1 | G37: 1 | H37: 1 | I37: 1 | J37: 1 | K37: =J37 -> 1 | L37: =K37 -> 1 | M37: =L37 -> 1 | N37: =M37 -> 1 | O37: =N37 -> 1 | P37: =O37 -> 1 | Q37: =P37 -> 1 | R37: =Q37 -> 1 | ... AC37: =AB37 -> 1
B38: Net increase in milk production in the year (million MT) | E38: =E36*E37/10 -> 0.008 | F38: =F36*F37/10 -> 0.016 | G38: =G36*G37/10 -> 0.024 | H38: =H36*H37/10 -> 0.032 | I38: =I36*I37/10 -> 0.04 | J38: =J36*J37/10 -> 0.056 | K38: =J38 -> 0.056 | L38: =K38 -> 0.056 | M38: =L38 -> 0.056 | N38: =M38 -> 0.056 | O38: =N38 -> 0.056 | P38: =O38 -> 0.056 | Q38: =P38 -> 0.056 | R38: =Q38 -> 0.056 | ... AC38: =AB38 -> 0.056
B39: Net increase in milk production in the year ('000 Tonnes) | E39: =E38*1000 -> 8 | F39: =F38*1000 -> 16 | G39: =G38*1000 -> 24 | H39: =H38*1000 -> 32 | I39: =I38*1000 -> 40 | J39: =J38*1000 -> 56 | K39: =K38*1000 -> 56 | L39: =L38*1000 -> 56 | ... S39: =S38*1000 -> 56 | T39: =S39 -> 56 | U39: =T39 -> 56 | V39: =U39 -> 56 | W39: =V39 -> 56 | X39: =W39 -> 56 | Y39: =X39 -> 56 | Z39: =Y39 -> 56 | AA39: =Z39 -> 56 | ... AC39: =AB39 -> 56
B41: Weighted average milk yield, Kg/day | C41: =+C59*1.03 -> 4.6587415
B42: Milk Productivity with RBP Intervention (Kg/day/animal), Incremental | C42: =+C41*E59 -> 0.46587415
B43: Milk Poduction with RBP intervention (Million tonnes), Incremental | C43: Million Tonnes | E43: 0 | F43: =$C$42*E6*365/1000000000 -> 0.062236128 | G43: =$C$42*F6*365/1000000000 -> 0.12600265 | H43: =$C$42*G6*365/1000000000 -> 0.20201235 | I43: =$C$42*H6*365/1000000000 -> 0.30914011 | J43: =$C$42*I6*365/1000000000 -> 0.40688144 | K43: =$C$42*J6*365/1000000000 -> 0.46238382 | L43: =$C$42*K6*365/1000000000 -> 0.46238382 | M43: =$C$42*L6*365/1000000000 -> 0.46238382 | ... AC43: =$C$42*AB6*365/1000000000 -> 0.46238382
...

Sheet Feed and Fodder (E) Zone.1
A1: Contribution of Feed & Nutrition to Additional Milk Production
C2: Current | E2: 2011-12 | F2: 2012-13 | G2: 2013-14 | H2: 2014-15 | I2: 2015-16 | J2: 2016-17 | K2: 2017-18 | L2: 2018-19 | M2: 2019-20 | N2: 2020-21 | O2: 2021-22 | P2: 2022-23 | Q2: 2023-24 | R2: 2024-25 | S2: 2025-26 | T2: 2026-27 | U2: 2027-28 | V2: 2028-29 | W2: 2029-30 | X2: 2030-31 | Y2: 2031-32 | Z2: 2032-33 | AA2: 2033-34 | AB2: 2034-35 | AC2: 2036-37
A3: A. | B3: Ration Balancing Programme RBP
B4: PDAs (Nos.) | C4: 25 | E4: 830 | F4: 1270 | G4: 730 | H4: 730 | I4: 1630 | J4: 2010 | K4: =J4 -> 2010 | L4: =K4 -> 2010 | M4: =L4 -> 2010 | N4: =M4 -> 2010 | O4: =N4 -> 2010 | P4: =O4 -> 2010 | Q4: =P4 -> 2010 | R4: =Q4 -> 2010 | S4: =R4 -> 2010
B5: Villages (Nos) | E5: 5500 | F5: 11100 | G5: 17700 | H5: 27300 | I5: 35880 | J5: 40320 | K5: 40320 | L5: 40320 | M5: 40320 | N5: 40320 | O5: 40320 | P5: 40320 | Q5: 40320 | R5: 40320 | S5: 40320 | T5: 40320 | U5: 40320 | V5: 40320 | W5: 40320 | X5: 40320 | Y5: 40320 | Z5: 40320 | AA5: 40320 | AB5: 40320 | AC5: 40320
B6: Animals covered (Nos) | E6: 366000 | F6: 741000 | G6: 1188000 | H6: 1818000 | I6: 2392800 | J6: 2719200 | K6: 2719200 | L6: 2719200 | M6: 2719200 | N6: 2719200 | O6: 2719200 | P6: 2719200 | Q6: 2719200 | R6: 2719200 | S6: 2719200 | T6: 2719200 | U6: 2719200 | V6: 2719200 | W6: 2719200 | X6: 2719200 | Y6: 2719200 | Z6: 2719200 | AA6: 2719200 | AB6: 2719200 | AC6: 2719200
B7: Average increase in milk production due to the programme (KgPD/Animal) | E7: ='Feed and Fodder'!S14 -> 0.5 | F7: =E7 -> 0.5 | G7: =F7 -> 0.5 | H7: =G7 -> 0.5 | I7: =H7 -> 0.5 | J7: =I7 -> 0.5 | K7: =J7 -> 0.5 | L7: =K7 -> 0.5 | M7: =L7 -> 0.5 | ... AC7: =AB7 -> 0.5
B8: Net increase in milk production in the year (million MT*) | E8: =E6*E7*365/1000000000 -> 0.066795 | F8: =F6*F7*365/1000000000 -> 0.1352325 | G8: =G6*G7*365/1000000000 -> 0.21681 | H8: =H6*H7*365/1000000000 -> 0.331785 | I8: =I6*I7*365/1000000000 -> 0.436686 | J8: =J6*J7*365/1000000000 -> 0.496254 | K8: =K6*K7*365/1000000000 -> 0.496254 | L8: =L6*L7*365/1000000000 -> 0.496254 | ... AC8: =AC6*AC7*365/1000000000 -> 0.496254
A10: B | B10: Fodder Seed
B11: Fodder Seed Plants (Nos) | E11: 1 | F11: 2 | G11: 4 | H11: 5 | I11: 6 | J11: 7 | K11: =J11 -> 7 | L11: =K11 -> 7 | M11: =L11 -> 7 | N11: =M11 -> 7 | O11: =N11 -> 7 | P11: =O11 -> 7 | Q11: =P11 -> 7 | R11: =Q11 -> 7 | ... AC11: =AB11 -> 7
B12: Capacity of Fodder Seed Plants (MTD) | E12: 10 | F12: 10 | G12: 10 | H12: 10 | I12: 10 | J12: 10 | K12: 10 | L12: 10 | M12: 10 | N12: 10 | O12: 10 | P12: 10 | Q12: 10 | R12: 10 | S12: 10 | T12: =S12 -> 10 | U12: =T12 -> 10 | V12: =U12 -> 10 | W12: =V12 -> 10 | X12: =W12 -> 10 | Y12: =X12 -> 10 | Z12: =Y12 -> 10 | AA12: =Z12 -> 10 | ... AC12: =AB12 -> 10
B13: Anticipated annual Fodder Seed Production (MT) | E13: 300 | F13: 600 | G13: 1200 | H13: 1500 | I13: 1800 | J13: 2100 | K13: =J13 -> 2100 | L13: =K13 -> 2100 | M13: =L13 -> 2100 | N13: =M13 -> 2100 | O13: =N13 -> 2100 | P13: =O13 -> 2100 | Q13: =P13 -> 2100 | R13: =Q13 -> 2100 | ... AC13: =AB13 -> 2100
B14: Fodder seed required per hactare (Kg) | E14: 50 | F14: 50 | G14: 50 | H14: 50 | I14: 50 | J14: 50 | K14: 50 | L14: 50 | M14: 50 | N14: 50 | O14: 50 | P14: 50 | Q14: 50 | R14: 50 | S14: 50 | T14: =S14 -> 50 | U14: =T14 -> 50 | V14: =U14 -> 50 | W14: =V14 -> 50 | X14: =W14 -> 50 | Y14: =X14 -> 50 | Z14: =Y14 -> 50 | AA14: =Z14 -> 50 | ... AC14: =AB14 -> 50
B15: Total area under fodder seed production (ha) | E15: =E13*1000/E14 -> 6000 | F15: =F13*1000/F14 -> 12000 | G15: =G13*1000/G14 -> 24000 | H15: =H13*1000/H14 -> 30000 | I15: =I13*1000/I14 -> 36000 | J15: =J13*1000/J14 -> 42000 | K15: =K13*1000/K14 -> 42000 | L15: =L13*1000/L14 -> 42000 | ... S15: =S13*1000/S14 -> 42000 | T15: =S15 -> 42000 | U15: =T15 -> 42000 | V15: =U15 -> 42000 | W15: =V15 -> 42000 | X15: =W15 -> 42000 | Y15: =X15 -> 42000 | Z15: =Y15 -> 42000 | AA15: =Z15 -> 42000 | ... AC15: =AB15 -> 42000
B16: Increase in fodder production per hactare (MT) | E16: 40 | F16: 40 | G16: 40 | H16: 40 | I16: 40 | J16: 40 | K16: 40 | L16: 40 | M16: 40 | N16: 40 | O16: 40 | P16: 40 | Q16: 40 | R16: 40 | S16: 40 | T16: =S16 -> 40 | U16: =T16 -> 40 | V16: =U16 -> 40 | W16: =V16 -> 40 | X16: =W16 -> 40 | Y16: =X16 -> 40 | Z16: =Y16 -> 40 | AA16: =Z16 -> 40 | ... AC16: =AB16 -> 40
B17: Annual increase in fodder production (million MT) | E17: =E15*E16/1000000 -> 0.24 | F17: =F15*F16/1000000 -> 0.48 | G17: =G15*G16/1000000 -> 0.96 | H17: =H15*H16/1000000 -> 1.2 | I17: =I15*I16/1000000 -> 1.44 | J17: =J15*J16/1000000 -> 1.68 | K17: =K15*K16/1000000 -> 1.68 | L17: =L15*L16/1000000 -> 1.68 | ... S17: =S15*S16/1000000 -> 1.68 | T17: =S17 -> 1.68 | U17: =T17 -> 1.68 | V17: =U17 -> 1.68 | W17: =V17 -> 1.68 | X17: =W17 -> 1.68 | Y17: =X17 -> 1.68 | Z17: =Y17 -> 1.68 | AA17: =Z17 -> 1.68 | ... AC17: =AB17 -> 1.68
B18: Increase in milk production for every 10 Kg fodder (Kg) | E18: 1 | F18: 1 | G18: 1 | H18: 1 | I18: 1 | J18: 1 | K18: 1 | L18: 1 | M18: 1 | N18: 1 | O18: 1 | P18: 1 | Q18: 1 | R18: 1 | S18: 1 | T18: =S18 -> 1 | U18: =T18 -> 1 | V18: =U18 -> 1 | W18: =V18 -> 1 | X18: =W18 -> 1 | Y18: =X18 -> 1 | Z18: =Y18 -> 1 | AA18: =Z18 -> 1 | ... AC18: =AB18 -> 1
B19: Net increase in milk production in the year (million MT) | E19: =E17*E18/10 -> 0.024 | F19: =F17*F18/10 -> 0.048 | G19: =G17*G18/10 -> 0.096 | H19: =H17*H18/10 -> 0.12 | I19: =I17*I18/10 -> 0.144 | J19: =J17*J18/10 -> 0.168 | K19: =K17*K18/10 -> 0.168 | L19: =L17*L18/10 -> 0.168 | ... S19: =S17*S18/10 -> 0.168 | T19: =S19 -> 0.168 | U19: =T19 -> 0.168 | V19: =U19 -> 0.168 | W19: =V19 -> 0.168 | X19: =W19 -> 0.168 | Y19: =X19 -> 0.168 | Z19: =Y19 -> 0.168 | AA19: =Z19 -> 0.168 | ... AC19: =AB19 -> 0.168
B20: Net increase in milk production in the year ('000 Tonnes) | E20: =E19*1000 -> 24 | F20: =F19*1000 -> 48 | G20: =G19*1000 -> 96 | H20: =H19*1000 -> 120 | I20: =I19*1000 -> 144 | J20: =J19*1000 -> 168 | K20: =K19*1000 -> 168 | L20: =L19*1000 -> 168 | ... S20: =S19*1000 -> 168 | T20: =S20 -> 168 | U20: =T20 -> 168 | V20: =U20 -> 168 | W20: =V20 -> 168 | X20: =W20 -> 168 | Y20: =X20 -> 168 | Z20: =Y20 -> 168 | AA20: =Z20 -> 168 | ... AC20: =AB20 -> 168
A22: C | B22: Straw Densification Plants ( Nos.) | E22: 0 | F22: 1 | G22: 1 | H22: 2 | I22: 2 | J22: 2 | K22: =J22 -> 2 | L22: =K22 -> 2 | M22: =L22 -> 2 | N22: =M22 -> 2 | O22: =N22 -> 2 | P22: =O22 -> 2 | Q22: =P22 -> 2 | R22: =Q22 -> 2 | ... AC22: =AB22 -> 2
B23: Capacity of Straw Densification Plants (MTD) | E23: 40 | F23: 40 | G23: 40 | H23: 40 | I23: 40 | J23: 40 | K23: 40 | L23: 40 | M23: 40 | N23: 40 | O23: 40 | P23: 40 | Q23: 40 | R23: 40 | S23: 40 | T23: 40 | U23: 40 | V23: 40 | W23: 40 | X23: 40 | Y23: 40 | Z23: 40 | AA23: 40 | AB23: 40 | AC23: 40
B24: Anticipated Annual Production (MT) | E24: =E22*E23*300 -> 0 | F24: =F22*F23*300 -> 12000 | G24: =G22*G23*300 -> 12000 | H24: =H22*H23*300 -> 24000 | I24: =I22*I23*300 -> 24000 | J24: =J22*J23*300 -> 24000 | K24: =K22*K23*300 -> 24000 | L24: =L22*L23*300 -> 24000 | ... AC24: =AC22*AC23*300 -> 24000
A25: C | B25: Devt of permanent pasture & common grazing lands
B26: Live Fencing, Plantation, Perennial Grass Seeding, Land and Irrigation Development (Area to be covered) | E26: 400 | F26: 800 | G26: 1200 | H26: 1600 | I26: 2000 | J26: 2800 | K26: =J26 -> 2800 | L26: =K26 -> 2800 | M26: =L26 -> 2800 | N26: =M26 -> 2800 | O26: =N26 -> 2800 | P26: =O26 -> 2800 | Q26: =P26 -> 2800 | R26: =Q26 -> 2800 | ... AC26: =AB26 -> 2800
B27: Incremental Biomass (From 0.75 MT/ hect/yr to 5.75 MT/hect/yr) | E27: =E26*5 -> 2000 | F27: =F26*5 -> 4000 | G27: =G26*5 -> 6000 | H27: =H26*5 -> 8000 | I27: =I26*5 -> 10000 | J27: =J26*5 -> 14000 | K27: =J27 -> 14000 | L27: =K27 -> 14000 | M27: =L27 -> 14000 | N27: =M27 -> 14000 | O27: =N27 -> 14000 | P27: =O27 -> 14000 | Q27: =P27 -> 14000 | R27: =Q27 -> 14000 | ... AC27: =AB27 -> 14000
B28: Annual increase in fodder production (million MT) | E28: =E27/1000000 -> 0.002 | F28: =F27/1000000 -> 0.004 | G28: =G27/1000000 -> 0.006 | H28: =H27/1000000 -> 0.008 | I28: =I27/1000000 -> 0.01 | J28: =J27/1000000 -> 0.014 | K28: =J28 -> 0.014 | L28: =K28 -> 0.014 | M28: =L28 -> 0.014 | N28: =M28 -> 0.014 | O28: =N28 -> 0.014 | P28: =O28 -> 0.014 | Q28: =P28 -> 0.014 | R28: =Q28 -> 0.014 | ... AC28: =AB28 -> 0.014
B29: Increase in milk production for every 10 Kg fodder (Kg) | E29: 1 | F29: 1 | G29: 1 | H29: 1 | I29: 1 | J29: 1 | K29: =J29 -> 1 | L29: =K29 -> 1 | M29: =L29 -> 1 | N29: =M29 -> 1 | O29: =N29 -> 1 | P29: =O29 -> 1 | Q29: =P29 -> 1 | R29: =Q29 -> 1 | ... AC29: =AB29 -> 1
B30: Net increase in milk production in the year (million MT) | E30: =E28*E29/10 -> 0.0002 | F30: =F28*F29/10 -> 0.0004 | G30: =G28*G29/10 -> 0.0006 | H30: =H28*H29/10 -> 0.0008 | I30: =I28*I29/10 -> 0.001 | J30: =J28*J29/10 -> 0.0014 | K30: =J30 -> 0.0014 | L30: =K30 -> 0.0014 | M30: =L30 -> 0.0014 | N30: =M30 -> 0.0014 | O30: =N30 -> 0.0014 | P30: =O30 -> 0.0014 | Q30: =P30 -> 0.0014 | R30: =Q30 -> 0.0014 | ... AC30: =AB30 -> 0.0014
B31: Net increase in milk production in the year ('000 Tonnes) | E31: =E30*1000 -> 0.2 | F31: =F30*1000 -> 0.4 | G31: =G30*1000 -> 0.6 | H31: =H30*1000 -> 0.8 | I31: =I30*1000 -> 1 | J31: =J30*1000 -> 1.4 | K31: =K30*1000 -> 1.4 | L31: =L30*1000 -> 1.4 | ... S31: =S30*1000 -> 1.4 | T31: =S31 -> 1.4 | U31: =T31 -> 1.4 | V31: =U31 -> 1.4 | W31: =V31 -> 1.4 | X31: =W31 -> 1.4 | Y31: =X31 -> 1.4 | Z31: =Y31 -> 1.4 | AA31: =Z31 -> 1.4 | ... AC31: =AB31 -> 1.4
A32: D | B32: Organising Varietal Demonstrations (1/10 of Hect) | E32: 20000 | F32: 40000 | G32: 60000 | H32: 80000 | I32: 100000 | J32: 140000 | K32: =J32 -> 140000 | L32: =K32 -> 140000 | M32: =L32 -> 140000 | N32: =M32 -> 140000 | O32: =N32 -> 140000 | P32: =O32 -> 140000 | Q32: =P32 -> 140000 | R32: =Q32 -> 140000 | ... AC32: =AB32 -> 140000
B33: Villages covered under Varietal Demonstrations (nos.) | E33: =E32/4 -> 5000 | F33: =F32/4 -> 10000 | G33: =G32/4 -> 15000 | H33: =H32/4 -> 20000 | I33: =I32/4 -> 25000 | J33: =J32/4 -> 35000 | K33: =J33 -> 35000 | L33: =K33 -> 35000 | M33: =L33 -> 35000 | N33: =M33 -> 35000 | O33: =N33 -> 35000 | P33: =O33 -> 35000 | Q33: =P33 -> 35000 | R33: =Q33 -> 35000 | ... AC33: =AB33 -> 35000
