Workbook

Sheet Productivity
B1: Unit | C1: 2011-12 | D1: 2012-13 | E1: 2013-14 | F1: 2014-15 | G1: 2015-16 | H1: 2016-17 | I1: 2017-18 | J1: 2018-19 | K1: 2019-20 | L1: 2020-21 | M1: 2021-22 | N1: 2022-23 | O1: 2023-24 | P1: 2024-25 | Q1: 2025-26 | R1: 2026-27 | S1: 2027-28 | T1: 2028-29 | U1: 2029-30 | V1: 2030-31 | W1: 2031-32 | X1: 2032-33 | Y1: 2033-34 | Z1: 2034-35 | AA1: 2035-36 | AB1: 2036-37 | AC1: 2037-38
A2: Highlights of AI delivery system
A3: 3000 AI centres would use semen doses from semen stations strengthened or established by NDSP
A4: All semen doses used by these 3000 AI centres would be from bulls produced by bull production programmes funded by NDSP
A5: AI delivery programme under NDSP would have a better conception rate and also the daughters born from such inseminations would be of higher genetic potential for milk production
A6: Increase in conception rate leads to a decrease in intercalving period and thus there is an increse in annual milk production.
A7: The project period has been assumed to be till 2036-37 for which benefits have been accounted, though NDSP would be funded in the first phase till 2016-17. The infrastructure created with respect to AI delivery, Semen stations and bull production would be available for a longer period of time.
G9: WOP
A10: Assumptions | B10: Unit | C10: Indig. Cattle | D10: CB Cattle | E10: Buffaloes
A11: Avg. lactation yield | B11: litres | C11: =Assumptions!C3 -> 779.64 | D11: =Assumptions!D3 -> 2507.185 | E11: =Assumptions!E3 -> 1668.415 | F11: =+SUMPRODUCT(C11:E11,C17:E17) -> 1650.9133 | G11: =3.94*365 -> 1438.1 | H11: =+D11/H42-1 -> 2.1839841 | I11: =+D11/C11-1 -> 2.215824
A12: Age at first calving | B12: years | C12: =Assumptions!C4 -> 4 | D12: =Assumptions!D4 -> 3 | E12: =Assumptions!E4 -> 4
A13: No. of lactations per animal | B13: Nos | C13: =Assumptions!C5 -> 5 | D13: =Assumptions!D5 -> 5 | E13: =Assumptions!E5 -> 5
A14: Anuual Increase in milk yield | B14: % | C14: =Assumptions!C6 -> 0.01 | D14: =Assumptions!D6 -> 0.01 | E14: =Assumptions!E6 -> 0.01
A15: Calving rate over pregnancy | C15: =Assumptions!C7 -> 0.9 | D15: =Assumptions!D7 -> 0.9 | E15: =Assumptions!E7 -> 0.9
A16: female calves alive rate | C16: =Assumptions!C8 -> 0.9 | D16: =Assumptions!D8 -> 0.9 | E16: =Assumptions!E8 -> 0.9 | G16: =514/C11 -> 0.65927864 | H16: =514/G11 -> 0.35741604
A17: Breed-wise Composition of AI done | B17: % | C17: 0.35 | D17: 0.35 | E17: =Assumptions!E9 -> 0.3 | G17: =+G16/15 -> 0.043951909 | H17: =+H16/15 -> 0.023827736
C19: Without NDSP | D19: With NDSP
A20: Conception rate | C20: =Assumptions!B14 -> 0.35 | D20: =Assumptions!C14 -> 0.45
A22: Lactation Period | B22: days | C22: =+Assumptions!C26 -> 305 | D22: =+Assumptions!D26 -> 305 | E22: =+Assumptions!E26 -> 305
A24: AI centres (Incremental) | B24: Nos. | C24: 700 | D24: 640 | E24: 840 | F24: 420 | G24: 400 | H24: 0 | I24: 0 | J24: 0 | K24: 0 | L24: 0 | M24: 0 | N24: 0 | O24: 0 | P24: 0 | Q24: 0 | R24: 0 | S24: 0 | T24: 0 | U24: 0 | V24: 0 | W24: 0 | X24: 0 | Y24: 0 | Z24: 0 | AA24: 0 | AB24: 0
A25: AI Nos. | B25: Lakhs | C25: 3.8 | D25: 8.7 | E25: 16.1 | F25: 23.4 | G25: 31.9 | H25: 38.5 | I25: =H25 -> 38.5 | J25: =I25 -> 38.5 | K25: =J25 -> 38.5 | L25: =K25 -> 38.5 | M25: =L25 -> 38.5 | N25: =M25 -> 38.5 | O25: =N25 -> 38.5 | P25: =O25 -> 38.5 | ... AB25: =AA25 -> 38.5
A26: AI Nos. | B26: Nos. | C26: =C25*100000 -> 380000 | D26: =D25*100000 -> 870000 | E26: =E25*100000 -> 1610000 | F26: =F25*100000 -> 2340000 | G26: =G25*100000 -> 3190000 | H26: =H25*100000 -> 3850000 | I26: =I25*100000 -> 3850000 | J26: =J25*100000 -> 3850000 | ... AB26: =AB25*100000 -> 3850000
C28: Without NDSP | D28: With NDSP | E28: Difference
A29: INDIGENOUS COWS
A30: AI Nos. | B30: Nos. | C30: =C26*$C$17 -> 133000 | D30: =D26*$C$17 -> 304500 | E30: =E26*$C$17 -> 563500 | F30: =F26*$C$17 -> 819000 | G30: =G26*$C$17 -> 1116500 | H30: =H26*$C$17 -> 1347500 | I30: =I26*$C$17 -> 1347500 | J30: =J26*$C$17 -> 1347500 | ... AB30: =AB26*$C$17 -> 1347500
A31: Inter-Calving period | C31: =280+60+((1/C20)-1)*22 -> 380.85714 | D31: =280+60+((1/D20)-1)*22 -> 366.88889 | E31: =C31-D31 -> 13.968254
A33: Impact of Increase in Conception rate
A34: Avg, Milk produced per day | B34: litres | C34: =C11/C22 -> 2.5561967
A35: Increase in milk production due to reduction in inter-calving period per animal | B35: litres | C35: =C34*E31 -> 35.705605
A36: Animals calved successfully | B36: Nos | D36: =C30*$D$20*$C$15*365/$D$31 -> 53587.682 | E36: =(D30*$D$20*$C$15*365/$D$31)+(C30*$D$20*$C$15*($D$31-365)/$D$31) -> 122964.91 | F36: =(E30*$D$20*$C$15*365/$D$31)+(D30*$D$20*$C$15*($D$31-365)/$D$31) -> 227677.46 | G36: =(F30*$D$20*$C$15*365/$D$31)+(E30*$D$20*$C$15*($D$31-365)/$D$31) -> 331162.26 | H36: =(G30*$D$20*$C$15*365/$D$31)+(F30*$D$20*$C$15*($D$31-365)/$D$31) -> 451562.18 | I36: =(H30*$D$20*$C$15*365/$D$31)+(G30*$D$20*$C$15*($D$31-365)/$D$31) -> 545255.84 | J36: =(I30*$D$20*$C$15*365/$D$31)+(H30*$D$20*$C$15*($D$31-365)/$D$31) -> 545737.5 | K36: =(J30*$D$20*$C$15*365/$D$31)+(I30*$D$20*$C$15*($D$31-365)/$D$31) -> 545737.5 | L36: =(K30*$D$20*$C$15*365/$D$31)+(J30*$D$20*$C$15*($D$31-365)/$D$31) -> 545737.5 | ... AB36: =(AA30*$D$20*$C$15*365/$D$31)+(Z30*$D$20*$C$15*($D$31-365)/$D$31) -> 545737.5
A37: Increase in milk production due to reduction in inter-calving period | B37: '000 Tonnes | D37: =D36*$C$35*1.03/1000/1000 -> 1.970782 | E37: =E36*$C$35*1.03/1000/1000 -> 4.5222524 | F37: =F36*$C$35*1.03/1000/1000 -> 8.3732423 | G37: =G36*$C$35*1.03/1000/1000 -> 12.179079 | H37: =H36*$C$35*1.03/1000/1000 -> 16.607 | I37: =I36*$C$35*1.03/1000/1000 -> 20.05275 | J37: =J36*$C$35*1.03/1000/1000 -> 20.070464 | K37: =K36*$C$35*1.03/1000/1000 -> 20.070464 | ... AB37: =AB36*$C$35*1.03/1000/1000 -> 20.070464
A39: Impact of better genetics
A40: Indig. Daughters born | B40: Lakhs | D40: =D36/2/100000*$C$16*Assumptions!$C$10 -> 0.12057228 | E40: =E36/2/100000*$C$16*Assumptions!$C$10 -> 0.27667104 | F40: =F36/2/100000*$C$16*Assumptions!$C$10 -> 0.51227428 | G40: =G36/2/100000*$C$16*Assumptions!$C$10 -> 0.74511508 | H40: =H36/2/100000*$C$16*Assumptions!$C$10 -> 1.0160149 | I40: =I36/2/100000*$C$16*Assumptions!$C$10 -> 1.2268256 | J40: =J36/2/100000*$C$16*Assumptions!$C$10 -> 1.2279094 | K40: =K36/2/100000*$C$16*Assumptions!$C$10 -> 1.2279094 | ... AB40: =AB36/2/100000*$C$16*Assumptions!$C$10 -> 1.2279094
A41: CB Daughters born | B41: Lakhs | D41: =D36/2/100000*$C$16*Assumptions!$C$11 -> 0.12057228 | E41: =E36/2/100000*$C$16*Assumptions!$C$11 -> 0.27667104 | F41: =F36/2/100000*$C$16*Assumptions!$C$11 -> 0.51227428 | G41: =G36/2/100000*$C$16*Assumptions!$C$11 -> 0.74511508 | H41: =H36/2/100000*$C$16*Assumptions!$C$11 -> 1.0160149 | I41: =I36/2/100000*$C$16*Assumptions!$C$11 -> 1.2268256 | J41: =J36/2/100000*$C$16*Assumptions!$C$11 -> 1.2279094 | K41: =K36/2/100000*$C$16*Assumptions!$C$11 -> 1.2279094 | ... AB41: =AB36/2/100000*$C$16*Assumptions!$C$11 -> 1.2279094
A42: WOP Yield | C42: 0.002 | H42: =+C11*(1+$C$42*5) -> 787.4364 | I42: =+H42*(1+$C$42) -> 789.01127 | J42: =+I42*(1+$C$42) -> 790.5893 | K42: =+J42*(1+$C$42) -> 792.17047 | L42: =+K42*(1+$C$42) -> 793.75481 | M42: =+L42*(1+$C$42) -> 795.34232 | N42: =+M42*(1+$C$42) -> 796.93301 | O42: =+N42*(1+$C$42) -> 798.52688 | P42: =+O42*(1+$C$42) -> 800.12393 | ... AB42: =+AA42*(1+$C$42) -> 819.53955
A43: Indig. Daughters calved & in milk | B43: Lakhs | H43: =D40 -> 0.12057228 | I43: =SUM(D40:E40) -> 0.39724332 | J43: =SUM(D40:F40) -> 0.9095176 | K43: =SUM(D40:G40) -> 1.6546327 | L43: =SUM(D40:H40) -> 2.6706476 | M43: =SUM(E40:I40) -> 3.776901 | N43: =SUM(F40:J40) -> 4.7281393 | O43: =SUM(G40:K40) -> 5.4437744 | P43: =SUM(H40:L40) -> 5.9265687 | Q43: =SUM(I40:M40) -> 6.1384631 | R43: =SUM(J40:N40) -> 6.1395469 | S43: =SUM(K40:O40) -> 6.1395469 | ... AB43: =SUM(T40:X40) -> 6.1395469
A44: Year wise Avg. lactation yield of Indig. Daughters | B44: litres | H44: =(1+$C$14*5)*C11 -> 818.622 | I44: =(1+$C$14)*H44 -> 826.80822 | J44: =(1+$C$14)*I44 -> 835.0763 | K44: =(1+$C$14)*J44 -> 843.42707 | L44: =(1+$C$14)*K44 -> 851.86134 | M44: =(1+$C$14)*L44 -> 860.37995 | N44: =(1+$C$14)*M44 -> 868.98375 | O44: =(1+$C$14)*N44 -> 877.67359 | P44: =(1+$C$14)*O44 -> 886.45032 | ... AB44: =(1+$C$14)*AA44 -> 998.87441
A45: Increase in lactation yield of Indig, daughters with respect to base population | B45: litres | H45: =+H44-H42 -> 31.1856 | I45: =+I44-I42 -> 37.796947 | J45: =+J44-J42 -> 44.487007 | K45: =+K44-K42 -> 51.256591 | L45: =+L44-L42 -> 58.106521 | M45: =+M44-M42 -> 65.037625 | N45: =+N44-N42 -> 72.05074 | O45: =+O44-O42 -> 79.146711 | ... AB45: =+AB44-AB42 -> 179.33486
A47: Incrmntl Milk production Matrix
A48: 1st lactation | B48: litres | H48: =H$45*D$40*100000 -> 376011.9 | I48: =I$45*E$40*100000 -> 1045732.1 | J48: =J$45*F$40*100000 -> 2278955 | K48: =K$45*G$40*100000 -> 3819205.9 | L48: =L$45*H$40*100000 -> 5903709.2 | M48: =M$45*I$40*100000 -> 7978982.6 | N48: =N$45*J$40*100000 -> 8847177.9 | O48: =O$45*K$40*100000 -> 9718498.8 | ... AB48: =AB$45*X$40*100000 -> 22020696
...

Sheet Assumptions
A1: Assumptions | C1: Value
A2: Parameter | B2: Unit | C2: Indig. Cattle | D2: CB Cattle | E2: Buffaloes | F2: Source
A3: Avg. lactation yield as on Year 2008 | B3: litres | C3: =2.136*365 -> 779.64 | D3: =6.869*365 -> 2507.185 | E3: =4.571*365 -> 1668.415 | F3: MINUTES OF THE MEETING OF THE TECHNICAL COMMITTEE OF DIRECTION FOR IMPROVEMENT OF ANIMAL HUSBANDRY AND DAIRYING STATISTICS UNDER THE CHAIRMANSHIP OF SHRI S.K. DAS, DIRECTOR GENERAL (DG), CENTRAL STATISTICAL ORGANISATION (CSO) HELD DURING 4 th -5th OCTOBER, 2010 AT AGARTALA, TRIPURA : Source : http://dahd.nic.in/
A4: Age at first calving | B4: years | C4: 4 | D4: 3 | E4: 4 | F4: NDDB project records - Kankrej
A5: No. of lactations per animal | B5: Nos | C5: 5 | D5: 5 | E5: 5 | F5: Expert opinion
A6: Anuual Increase in milk yield | B6: % | C6: 0.01 | D6: 0.01 | E6: 0.01 | F6: References for Genetic Progress: 1. Rendel J M and Robertson A. 1950 J. Genetics 50, 1-8; 2. Cunningham. E.P 1979, The importance of continuous genetic progress in adapted breeds. Report of the FAO Expert Consultation on Dairy Cattle Breeding in the Humid Tropics; pp 35-41, FAO Rome; 3. Van Vleck L D 1981 In: New Technology in Animal Breeding 221-242; Acad. Press London; 4. I.L. Mason and V. Buvauendran, 1982. Breeding plans for ruminant livestock in the tropics – FAO (1982) (Chapter 1.1.2 Improvement within breeds); 5. Smith C., 1988 – Application of embryo transfer in Animal breeding. Theriogenology 29, 1, 203-212;
A7: Calving rate over pregnancy | C7: 0.9 | D7: 0.9 | E7: 0.9 | F7: Expert opinion
A8: female calves alive rate | C8: 0.9 | D8: 0.9 | E8: 0.9 | F8: Expert opinion
A9: % AI done on | B9: % | C9: =F22+(F21*1/3) -> 0.2 | D9: =F20+(F21*2/3) -> 0.5 | E9: =F23 -> 0.3 | F9: NDDB internal sources; and expert opinion
A10: Daughters (Indig. Cattle) born to Indig. Cattle | C10: =F22/C9 -> 0.5
A11: Daughters (CB Cattle) born to Indig. Cattle | C11: =100%-C10 -> 0.5
A13: Avg. Conception rate | B13: Without NDSP | C13: With NDSP
A14: AI, FSP & Bull production (All 3 from NDP) | B14: 0.35 | C14: 0.45 | D14: 0.05 | E14: 0.05 | F14: Expert opinion
A15: FSP & Bull production (NDP bulls in NDP semen station but Non NDP AI) | B15: 0.35 | C15: 0.38 | D15: 0.05 | E15: 0.05 | F15: Expert opinion
A16: Bull production Programme(NDP bulls in non-NDP semen station and Non-NDP AI) | B16: 0.35 | C16: 0.36 | D16: 0.05 | E16: 0.05 | F16: Expert opinion
A17: NDP SS+Non NDP bulls(Non-NDP bulls in NDP semen station but non-NDP AI) | B17: 0.35 | C17: 0.37 | D17: 0.05 | E17: 0.05 | F17: Expert opinion
F19: Frozen Semen Production trend (2008-09) | G19: used on cattle
E20: CB | F20: 0.3 | G20: CB
E21: Exotic | F21: 0.3 | G21: 66% onCB; 33% on Indig.
E22: Indig | F22: 0.1 | G22: Indig
E23: Buff | F23: 0.3 | G23: Buff
A26: Lactation Period | B26: Days | C26: 305 | D26: 305 | E26: 305

Sheet Summary
C1: Unit | E1: 2011-12 | F1: 2012-13 | G1: 2013-14 | H1: 2014-15 | I1: 2015-16 | J1: 2016-17 | K1: 2017-18 | L1: 2018-19 | M1: 2019-20 | N1: 2020-21 | O1: 2021-22 | P1: 2022-23 | Q1: 2023-24 | R1: 2024-25 | S1: 2025-26 | T1: 2026-27 | U1: 2027-28 | V1: 2028-29 | W1: 2029-30 | X1: 2030-31 | Y1: 2031-32 | Z1: 2032-33 | AA1: 2033-34 | AB1: 2034-35 | AC1: 2035-36
B35: Import of 400 bulls
B36: 28 Semen Stations for strengthening
B37: 2 New Semen Station of 10 million semen doses capacity
B38: 3000 AI centres to be newly established
B40: Impact of Genetic Improvement programme under NDSP
B41: Incrmntl. Milk production | E41: 2011-12 | F41: 2012-13 | G41: 2013-14 | H41: 2014-15 | I41: 2015-16 | J41: 2016-17 | K41: 2017-18 | L41: 2018-19 | M41: 2019-20 | N41: 2020-21 | O41: 2021-22 | P41: 2022-23 | Q41: 2023-24 | R41: 2024-25 | S41: 2025-26 | T41: 2026-27 | U41: 2027-28 | V41: 2028-29 | W41: 2029-30 | X41: 2030-31 | Y41: 2031-32 | Z41: 2032-33 | AA41: 2033-34 | AB41: 2034-35 | AC41: 2035-36
B42: 1. Due to reduction in Inter-calving period
B43: NDSP - bulls, NDSP-SS and NDSP-AI | C43: '000 tonnes of Milk | D43: Total | E43: =SUM(E44:E46) -> 0 | F43: =SUM(F44:F46) -> 11.65017 | G43: =SUM(G44:G46) -> 27.007707 | H43: =SUM(H44:H46) -> 50.126789 | I43: =SUM(I44:I46) -> 73.159649 | J43: =SUM(J44:J46) -> 99.862696 | K43: =SUM(K44:K46) -> 120.84643 | L43: =SUM(L44:L46) -> 121.42819 | ... AC43: =SUM(AC44:AC46) -> 121.42819
D44: Indigenous Cows | E44: 0 | F44: 1.970782 | G44: 4.5222524 | H44: 8.3732423 | I44: 12.179079 | J44: 16.607 | K44: 20.05275 | L44: 20.070464 | M44: 20.070464 | N44: 20.070464 | O44: 20.070464 | P44: 20.070464 | Q44: 20.070464 | R44: 20.070464 | S44: 20.070464 | T44: 20.070464 | U44: 20.070464 | V44: 20.070464 | W44: 20.070464 | X44: 20.070464 | Y44: 20.070464 | Z44: 20.070464 | AA44: 20.070464 | AB44: 20.070464 | AC44: 20.070464
D45: Cross Bred Cows | E45: 0 | F45: 6.337688 | G45: 14.542768 | H45: 26.926873 | I45: 39.165775 | J45: 53.405189 | K45: 64.486115 | L45: 64.54308 | M45: 64.54308 | N45: 64.54308 | O45: 64.54308 | P45: 64.54308 | Q45: 64.54308 | R45: 64.54308 | S45: 64.54308 | T45: 64.54308 | U45: 64.54308 | V45: 64.54308 | W45: 64.54308 | X45: 64.54308 | Y45: 64.54308 | Z45: 64.54308 | AA45: 64.54308 | AB45: 64.54308 | AC45: 64.54308
D46: Boffaloes | E46: 0 | F46: 3.3416995 | G46: 7.9426867 | H46: 14.826673 | I46: 21.814795 | J46: 29.850508 | K46: 36.307566 | L46: 36.814644 | M46: 36.814644 | N46: 36.814644 | O46: 36.814644 | P46: 36.814644 | Q46: 36.814644 | R46: 36.814644 | S46: 36.814644 | T46: 36.814644 | U46: 36.814644 | V46: 36.814644 | W46: 36.814644 | X46: 36.814644 | Y46: 36.814644 | Z46: 36.814644 | AA46: 36.814644 | AB46: 36.814644 | AC46: 36.814644
B48: NDSP-Bulls, NDSP-SS, and non-NDSP-AI | C48: '000 tonnes of Milk | D48: Total | E48: =SUM(E49:E51) -> 0 | F48: =SUM(F49:F51) -> 5.357906 | G48: =SUM(G49:G51) -> 87.534778 | H48: =SUM(H49:H51) -> 197.62384 | I48: =SUM(I49:I51) -> 350.37973 | J48: =SUM(J49:J51) -> 559.22822 | K48: =SUM(K49:K51) -> 745.78771 | L48: =SUM(L49:L51) -> 754.64349 | ... AC48: =SUM(AC49:AC51) -> 754.64349
D49: Indigenous Cows | E49: ='NDSP Bull, SS & Non-NDSP AI'!C48 -> 0 | F49: 0.44603571 | G49: 7.278035 | H49: 16.304051 | I49: 28.841242 | J49: 45.977838 | K49: 61.167457 | L49: 61.605905 | M49: 61.605905 | N49: 61.605905 | O49: 61.605905 | P49: 61.605905 | Q49: 61.605905 | R49: 61.605905 | S49: 61.605905 | T49: 61.605905 | U49: 61.605905 | V49: 61.605905 | W49: 61.605905 | X49: 61.605905 | Y49: 61.605905 | Z49: 61.605905 | AA49: 61.605905 | AB49: 61.605905 | AC49: 61.605905
D50: Cross Bred Cows | E50: ='NDSP Bull, SS & Non-NDSP AI'!C95 -> 0 | F50: 3.5859308 | G50: 58.512199 | H50: 131.0774 | I50: 231.8709 | J50: 369.64158 | K50: 491.75944 | L50: 495.28436 | M50: 495.28436 | N50: 495.28436 | O50: 495.28436 | P50: 495.28436 | Q50: 495.28436 | R50: 495.28436 | S50: 495.28436 | T50: 495.28436 | U50: 495.28436 | V50: 495.28436 | W50: 495.28436 | X50: 495.28436 | Y50: 495.28436 | Z50: 495.28436 | AA50: 495.28436 | AB50: 495.28436 | AC50: 495.28436
D51: Boffaloes | E51: ='NDSP Bull, SS & Non-NDSP AI'!C124 -> 0 | F51: 1.3259394 | G51: 21.744544 | H51: 50.242397 | I51: 89.667588 | J51: 143.6088 | K51: 192.86082 | L51: 197.75322 | M51: 197.75322 | N51: 197.75322 | O51: 197.75322 | P51: 197.75322 | Q51: 197.75322 | R51: 197.75322 | S51: 197.75322 | T51: 197.75322 | U51: 197.75322 | V51: 197.75322 | W51: 197.75322 | X51: 197.75322 | Y51: 197.75322 | Z51: 197.75322 | AA51: 197.75322 | AB51: 197.75322 | AC51: 197.75322
B53: NDSP-Bulls, Non-NDSP-SS and Non-NDSP-AI | C53: '000 tonnes of Milk | D53: Total | E53: =SUM(E54:E56) -> 0 | F53: =SUM(F54:F56) -> 0 | G53: =SUM(G54:G56) -> 0 | H53: =SUM(H54:H56) -> 0 | I53: =SUM(I54:I56) -> 0 | J53: =SUM(J54:J56) -> 0 | K53: =SUM(K54:K56) -> 0 | L53: =SUM(L54:L56) -> 0 | ... AC53: =SUM(AC54:AC56) -> 0
D54: Indigenous Cows | E54: ='NDSP-Bull & Non-NDSP SS,AI'!C39 -> 0 | F54: ='NDSP-Bull & Non-NDSP SS,AI'!D39 -> 0 | G54: ='NDSP-Bull & Non-NDSP SS,AI'!E39 -> 0 | H54: ='NDSP-Bull & Non-NDSP SS,AI'!F39 -> 0 | I54: ='NDSP-Bull & Non-NDSP SS,AI'!G39 -> 0 | J54: ='NDSP-Bull & Non-NDSP SS,AI'!H39 -> 0 | K54: ='NDSP-Bull & Non-NDSP SS,AI'!I39 -> 0 | L54: ='NDSP-Bull & Non-NDSP SS,AI'!J39 -> 0 | ... AC54: ='NDSP-Bull & Non-NDSP SS,AI'!AA39 -> 0
D55: Cross Bred Cows | E55: ='NDSP-Bull & Non-NDSP SS,AI'!C86 -> 0 | F55: ='NDSP-Bull & Non-NDSP SS,AI'!D86 -> 0 | G55: ='NDSP-Bull & Non-NDSP SS,AI'!E86 -> 0 | H55: ='NDSP-Bull & Non-NDSP SS,AI'!F86 -> 0 | I55: ='NDSP-Bull & Non-NDSP SS,AI'!G86 -> 0 | J55: ='NDSP-Bull & Non-NDSP SS,AI'!H86 -> 0 | K55: ='NDSP-Bull & Non-NDSP SS,AI'!I86 -> 0 | L55: ='NDSP-Bull & Non-NDSP SS,AI'!J86 -> 0 | ... AC55: ='NDSP-Bull & Non-NDSP SS,AI'!AA86 -> 0
D56: Boffaloes | E56: ='NDSP-Bull & Non-NDSP SS,AI'!C115 -> 0 | F56: ='NDSP-Bull & Non-NDSP SS,AI'!D115 -> 0 | G56: ='NDSP-Bull & Non-NDSP SS,AI'!E115 -> 0 | H56: ='NDSP-Bull & Non-NDSP SS,AI'!F115 -> 0 | I56: ='NDSP-Bull & Non-NDSP SS,AI'!G115 -> 0 | J56: ='NDSP-Bull & Non-NDSP SS,AI'!H115 -> 0 | K56: ='NDSP-Bull & Non-NDSP SS,AI'!I115 -> 0 | L56: ='NDSP-Bull & Non-NDSP SS,AI'!J115 -> 0 | ... AC56: ='NDSP-Bull & Non-NDSP SS,AI'!AA115 -> 0
B58: Non-NDSP - Bulls, NDSP- SS and Non-NDSP-AI | C58: '000 tonnes of Milk | D58: Total | E58: =SUM(E59:E61) -> 0 | F58: =SUM(F59:F61) -> 260.61762 | G58: =SUM(G59:G61) -> 354.67998 | H58: =SUM(H59:H61) -> 401.2177 | I58: =SUM(I59:I61) -> 363.83561 | J58: =SUM(J59:J61) -> 277.11839 | K58: =SUM(K59:K61) -> 202.43192 | L58: =SUM(L59:L61) -> 198.61393 | ... AC58: =SUM(AC59:AC61) -> 198.61393
D59: Indigenous Cows | E59: 0 | F59: 21.694287 | G59: 29.08284 | H59: 32.821471 | I59: 29.638272 | J59: 22.486973 | K59: 16.413134 | L59: 16.214002 | M59: 16.214002 | N59: 16.214002 | O59: 16.214002 | P59: 16.214002 | Q59: 16.214002 | R59: 16.214002 | S59: 16.214002 | T59: 16.214002 | U59: 16.214002 | V59: 16.214002 | W59: 16.214002 | X59: 16.214002 | Y59: 16.214002 | Z59: 16.214002 | AA59: 16.214002 | AB59: 16.214002 | AC59: 16.214002
D60: Cross Bred Cows | E60: 0 | F60: 174.41252 | G60: 233.81323 | H60: 263.87019 | I60: 238.27867 | J60: 180.78537 | K60: 131.95438 | L60: 130.35344 | M60: 130.35344 | N60: 130.35344 | O60: 130.35344 | P60: 130.35344 | Q60: 130.35344 | R60: 130.35344 | S60: 130.35344 | T60: 130.35344 | U60: 130.35344 | V60: 130.35344 | W60: 130.35344 | X60: 130.35344 | Y60: 130.35344 | Z60: 130.35344 | AA60: 130.35344 | AB60: 130.35344 | AC60: 130.35344
D61: Boffaloes | E61: 0 | F61: 64.510813 | G61: 91.783906 | H61: 104.52604 | I61: 95.918672 | J61: 73.846046 | K61: 54.064409 | L61: 52.046491 | M61: 52.046491 | N61: 52.046491 | O61: 52.046491 | P61: 52.046491 | Q61: 52.046491 | R61: 52.046491 | S61: 52.046491 | T61: 52.046491 | U61: 52.046491 | V61: 52.046491 | W61: 52.046491 | X61: 52.046491 | Y61: 52.046491 | Z61: 52.046491 | AA61: 52.046491 | AB61: 52.046491 | AC61: 52.046491
B62: Sub-Total (1) | C62: '000 tonnes of Milk | E62: =E43+E48+E53+E58 -> 0 | F62: =F43+F48+F53+F58 -> 277.62569 | G62: =G43+G48+G53+G58 -> 469.22246 | H62: =H43+H48+H53+H58 -> 648.96833 | I62: =I43+I48+I53+I58 -> 787.37499 | J62: =J43+J48+J53+J58 -> 936.20931 | K62: =K43+K48+K53+K58 -> 1069.0661 | L62: =L43+L48+L53+L58 -> 1074.6856 | ... AC62: =AC43+AC48+AC53+AC58 -> 1074.6856
B64: 2. Due to Better genetics
B65: NDSP - bulls, NDSP-SS and NDSP-AI | C65: '000 tonnes of Milk | D65: Total | E65: =SUM(E66:E69) -> 0 | F65: =SUM(F66:F69) -> 0 | G65: =SUM(G66:G69) -> 0 | H65: =SUM(H66:H69) -> 0 | I65: =SUM(I66:I69) -> 24.441461 | J65: =SUM(J66:J69) -> 84.040327 | K65: =SUM(K66:K69) -> 199.28542 | L65: =SUM(L66:L69) -> 375.32312 | ... AC65: =SUM(AC66:AC69) -> 2441.1065
D66: Indigenous-indigenous | E66: 0 | F66: 0 | G66: 0 | H66: 0 | I66: 0 | J66: 0.38529833 | K66: 1.4588509 | L66: 3.7996349 | M66: 7.7252493 | N66: 13.795016 | O66: 21.617065 | P66: 29.651502 | Q66: 37.316151 | R66: 44.303963 | S66: 50.066312 | T66: 54.620576 | U66: 59.214611 | V66: 63.862643 | W66: 68.565268 | X66: 73.323047 | Y66: 78.136548 | Z66: 83.006344 | AA66: 87.933015 | AB66: 92.917146 | AC66: 97.959329
D67: Indigenous-Crossbred | E67: 0 | F67: 0 | G67: 0 | H67: 0 | I67: 21.343832 | J67: 70.430883 | K67: 161.36767 | L67: 293.73801 | M67: 474.27662 | N67: 671.03751 | O67: 840.44014 | P67: 967.99403 | Q67: 1054.1144 | R67: 1092.0664 | S67: 1092.4524 | T67: 1092.4534 | U67: 1092.4534 | V67: 1092.4534 | W67: 1092.4534 | X67: 1092.4534 | Y67: 1092.4534 | Z67: 1092.4534 | AA67: 1092.4534 | AB67: 1092.4534 | AC67: 1092.4534
D68: CrossBred cows | E68: 0 | F68: 0 | G68: 0 | H68: 0 | I68: 3.097629 | J68: 11.714303 | K68: 30.47488 | L68: 61.895487 | M68: 110.41727 | N68: 172.85125 | O68: 236.87407 | P68: 297.82159 | Q68: 353.24807 | R68: 398.78376 | S68: 434.5921 | T68: 470.64786 | U68: 507.06388 | V68: 543.84405 | W68: 580.99203 | X68: 618.51149 | Y68: 656.40614 | Z68: 694.67974 | AA68: 733.33608 | AB68: 772.37898 | AC68: 811.81231
D69: Buffaloes | E69: 0 | F69: 0 | G69: 0 | H69: 0 | I69: 0 | J69: 1.5098422 | K69: 5.9840236 | L69: 15.889996 | M69: 32.850427 | N69: 59.246672 | O69: 93.896929 | P69: 130.51402 | Q69: 165.76945 | R69: 198.03939 | S69: 224.98318 | T69: 246.31386 | U69: 266.90563 | V69: 287.66145 | W69: 308.62483 | X69: 329.79784 | Y69: 351.18258 | Z69: 372.78117 | AA69: 394.59574 | AB69: 416.62846 | AC69: 438.88151
B71: NDSP-Bulls, NDSP-SS, and non-NDSP-AI | C71: '000 tonnes of Milk | D71: Total | E71: =SUM(E72:E75) -> 0 | F71: =SUM(F72:F75) -> 0 | G71: =SUM(G72:G75) -> 0 | H71: =SUM(H72:H75) -> 0 | I71: =SUM(I72:I75) -> 18.086795 | J71: =SUM(J72:J75) -> 332.20005 | K71: =SUM(K72:K75) -> 1115.7534 | L71: =SUM(L72:L75) -> 2613.6074 | ... AC71: =SUM(AC72:AC75) -> 34619.069
D72: Indigenous-indigenous | E72: 0 | F72: 0 | G72: 0 | H72: 0 | I72: 0 | J72: 0.29947207 | K72: 6.2211157 | L72: 21.964868 | M72: 54.115656 | N72: 112.25362 | O72: 198.72245 | P72: 290.13992 | Q72: 381.24653 | R72: 465.53407 | S72: 533.51828 | T72: 582.65285 | U72: 631.09509 | V72: 680.00337 | W72: 729.40074 | X72: 779.29208 | Y72: 829.68234 | Z72: 880.57649 | AA72: 931.97959 | AB72: 983.89672 | AC72: 1036.333
D73: Indigenous-Crossbred | E73: 0 | F73: 0 | G73: 0 | H73: 0 | I73: 13.271548 | J73: 230.22162 | K73: 721.80353 | L73: 1594.439 | M73: 2988.099 | N73: 4835.6658 | O73: 6506.0901 | P73: 7902.272 | Q73: 8917.4004 | R73: 9411.5042 | S73: 9438.4297 | T73: 9438.8191 | U73: 9438.8191 | V73: 9438.8191 | W73: 9438.8191 | X73: 9438.8191 | Y73: 9438.8191 | Z73: 9438.8191 | AA73: 9438.8191 | AB73: 9438.8191 | AC73: 9438.8191
D74: CrossBred cows | E74: 0 | F74: 0 | G74: 0 | H74: 0 | I74: 4.8152473 | J74: 100.03006 | K74: 353.17574 | L74: 870.13211 | M74: 1804.9394 | N74: 3195.282 | O74: 4665.1946 | P74: 6130.1086 | Q74: 7485.3781 | R74: 8578.5044 | S74: 9368.545 | T74: 10147.454 | U74: 10933.856 | V74: 11728.122 | W74: 12530.331 | X74: 13340.562 | Y74: 14158.895 | Z74: 14985.412 | AA74: 15820.193 | AB74: 16663.323 | AC74: 17514.884
D75: Buffaloes | E75: 0 | F75: 0 | G75: 0 | H75: 0 | I75: 0 | J75: 1.6488957 | K75: 34.553028 | L75: 127.07149 | M75: 319.48901 | N75: 670.79804 | O75: 1202.9695 | P75: 1789.3501 | Q75: 2378.4298 | R75: 2929.1209 | S75: 3383.046 | T75: 3717.2067 | U75: 4029.2772 | V75: 4343.0425 | W75: 4659.9454 | X75: 4980.0173 | Y75: 5303.29 | Z75: 5629.7954 | AA75: 5959.5658 | AB75: 6292.6339 | AC75: 6629.0328
B77: NDSP-Bulls, Non-NDSP-SS and Non-NDSP-AI | C77: '000 tonnes of Milk | D77: Total | E77: =SUM(E78:E81) -> 0 | F77: =SUM(F78:F81) -> 0 | G77: =SUM(G78:G81) -> 0 | H77: =SUM(H78:H81) -> 0 | I77: =SUM(I78:I81) -> 0 | J77: =SUM(J78:J81) -> 0 | K77: =SUM(K78:K81) -> 0 | L77: =SUM(L78:L81) -> 0 | ... AC77: =SUM(AC78:AC81) -> 0
D78: Indigenous-indigenous | E78: ='NDSP-Bull & Non-NDSP SS,AI'!C57 -> 0 | F78: ='NDSP-Bull & Non-NDSP SS,AI'!D57 -> 0 | G78: ='NDSP-Bull & Non-NDSP SS,AI'!E57 -> 0 | H78: ='NDSP-Bull & Non-NDSP SS,AI'!F57 -> 0 | I78: ='NDSP-Bull & Non-NDSP SS,AI'!G57 -> 0 | J78: ='NDSP-Bull & Non-NDSP SS,AI'!H57 -> 0 | K78: ='NDSP-Bull & Non-NDSP SS,AI'!I57 -> 0 | L78: ='NDSP-Bull & Non-NDSP SS,AI'!J57 -> 0 | ... AC78: ='NDSP-Bull & Non-NDSP SS,AI'!AA57 -> 0
D79: Indigenous-Crossbred | E79: ='NDSP-Bull & Non-NDSP SS,AI'!C71 -> 0 | F79: ='NDSP-Bull & Non-NDSP SS,AI'!D71 -> 0 | G79: ='NDSP-Bull & Non-NDSP SS,AI'!E71 -> 0 | H79: ='NDSP-Bull & Non-NDSP SS,AI'!F71 -> 0 | I79: ='NDSP-Bull & Non-NDSP SS,AI'!G71 -> 0 | J79: ='NDSP-Bull & Non-NDSP SS,AI'!H71 -> 0 | K79: ='NDSP-Bull & Non-NDSP SS,AI'!I71 -> 0 | L79: ='NDSP-Bull & Non-NDSP SS,AI'!J71 -> 0 | ... AC79: ='NDSP-Bull & Non-NDSP SS,AI'!AA71 -> 0
D80: CrossBred cows | E80: ='NDSP-Bull & Non-NDSP SS,AI'!C102 -> 0 | F80: ='NDSP-Bull & Non-NDSP SS,AI'!D102 -> 0 | G80: ='NDSP-Bull & Non-NDSP SS,AI'!E102 -> 0 | H80: ='NDSP-Bull & Non-NDSP SS,AI'!F102 -> 0 | I80: ='NDSP-Bull & Non-NDSP SS,AI'!G102 -> 0 | J80: ='NDSP-Bull & Non-NDSP SS,AI'!H102 -> 0 | K80: ='NDSP-Bull & Non-NDSP SS,AI'!I102 -> 0 | L80: ='NDSP-Bull & Non-NDSP SS,AI'!J102 -> 0 | ... AC80: ='NDSP-Bull & Non-NDSP SS,AI'!AA102 -> 0
...

Sheet NDSP Bull,SS,AI
B1: Unit | C1: 2011-12 | D1: 2012-13 | E1: 2013-14 | F1: 2014-15 | G1: 2015-16 | H1: 2016-17 | I1: 2017-18 | J1: 2018-19 | K1: 2019-20 | L1: 2020-21 | M1: 2021-22 | N1: 2022-23 | O1: 2023-24 | P1: 2024-25 | Q1: 2025-26 | R1: 2026-27 | S1: 2027-28 | T1: 2028-29 | U1: 2029-30 | V1: 2030-31 | W1: 2031-32 | X1: 2032-33 | Y1: 2033-34 | Z1: 2034-35 | AA1: 2035-36 | AB1: 2036-37 | AC1: 2037-38
A2: Highlights of AI delivery system
A3: 3000 AI centres would use semen doses from semen stations strengthened or established by NDSP
A4: All semen doses used by these 3000 AI centres would be from bulls produced by bull production programmes funded by NDSP
A5: AI delivery programme under NDSP would have a better conception rate and also the daughters born from such inseminations would be of higher genetic potential for milk production
A6: Increase in conception rate leads to a decrease in intercalving period and thus there is an increse in annual milk production.
A7: The project period has been assumed to be till 2036-37 for which benefits have been accounted, though NDSP would be funded in the first phase till 2016-17. The infrastructure created with respect to AI delivery, Semen stations and bull production would be available for a longer period of time.
G9: WOP
A10: Assumptions | B10: Unit | C10: Indig. Cattle | D10: CB Cattle | E10: Buffaloes
A11: Avg. lactation yield | B11: litres | C11: =Assumptions!C3 -> 779.64 | D11: =Assumptions!D3 -> 2507.185 | E11: =Assumptions!E3 -> 1668.415 | F11: =+SUMPRODUCT(C11:E11,C17:E17) -> 1650.9133 | G11: =3.94*365 -> 1438.1 | H11: =+D11/H42-1 -> 2.1839841 | I11: =+D11/C11-1 -> 2.215824
A12: Age at first calving | B12: years | C12: =Assumptions!C4 -> 4 | D12: =Assumptions!D4 -> 3 | E12: =Assumptions!E4 -> 4
A13: No. of lactations per animal | B13: Nos | C13: =Assumptions!C5 -> 5 | D13: =Assumptions!D5 -> 5 | E13: =Assumptions!E5 -> 5
A14: Anuual Increase in milk yield | B14: % | C14: =Assumptions!C6 -> 0.01 | D14: =Assumptions!D6 -> 0.01 | E14: =Assumptions!E6 -> 0.01
A15: Calving rate over pregnancy | C15: =Assumptions!C7 -> 0.9 | D15: =Assumptions!D7 -> 0.9 | E15: =Assumptions!E7 -> 0.9
A16: female calves alive rate | C16: =Assumptions!C8 -> 0.9 | D16: =Assumptions!D8 -> 0.9 | E16: =Assumptions!E8 -> 0.9 | G16: =514/C11 -> 0.65927864 | H16: =514/G11 -> 0.35741604
A17: Breed-wise Composition of AI done | B17: % | C17: 0.35 | D17: 0.35 | E17: =Assumptions!E9 -> 0.3 | G17: =+G16/15 -> 0.043951909 | H17: =+H16/15 -> 0.023827736
C19: Without NDSP | D19: With NDSP
A20: Conception rate | C20: =Assumptions!B14 -> 0.35 | D20: =Assumptions!C14 -> 0.45
A22: Lactation Period | B22: days | C22: =+Assumptions!C26 -> 305 | D22: =+Assumptions!D26 -> 305 | E22: =+Assumptions!E26 -> 305
A24: AI centres (Incremental) | B24: Nos. | C24: 700 | D24: 640 | E24: 840 | F24: 420 | G24: 400 | H24: 0 | I24: 0 | J24: 0 | K24: 0 | L24: 0 | M24: 0 | N24: 0 | O24: 0 | P24: 0 | Q24: 0 | R24: 0 | S24: 0 | T24: 0 | U24: 0 | V24: 0 | W24: 0 | X24: 0 | Y24: 0 | Z24: 0 | AA24: 0 | AB24: 0
A25: AI Nos. | B25: Lakhs | C25: 3.8 | D25: 8.7 | E25: 16.1 | F25: 23.4 | G25: 31.9 | H25: 38.5 | I25: =H25 -> 38.5 | J25: =I25 -> 38.5 | K25: =J25 -> 38.5 | L25: =K25 -> 38.5 | M25: =L25 -> 38.5 | N25: =M25 -> 38.5 | O25: =N25 -> 38.5 | P25: =O25 -> 38.5 | ... AB25: =AA25 -> 38.5
A26: AI Nos. | B26: Nos. | C26: =C25*100000 -> 380000 | D26: =D25*100000 -> 870000 | E26: =E25*100000 -> 1610000 | F26: =F25*100000 -> 2340000 | G26: =G25*100000 -> 3190000 | H26: =H25*100000 -> 3850000 | I26: =I25*100000 -> 3850000 | J26: =J25*100000 -> 3850000 | ... AB26: =AB25*100000 -> 3850000
C28: Without NDSP | D28: With NDSP | E28: Difference
A29: INDIGENOUS COWS
A30: AI Nos. | B30: Nos. | C30: =C26*$C$17 -> 133000 | D30: =D26*$C$17 -> 304500 | E30: =E26*$C$17 -> 563500 | F30: =F26*$C$17 -> 819000 | G30: =G26*$C$17 -> 1116500 | H30: =H26*$C$17 -> 1347500 | I30: =I26*$C$17 -> 1347500 | J30: =J26*$C$17 -> 1347500 | ... AB30: =AB26*$C$17 -> 1347500
A31: Inter-Calving period | C31: =280+60+((1/C20)-1)*22 -> 380.85714 | D31: =280+60+((1/D20)-1)*22 -> 366.88889 | E31: =C31-D31 -> 13.968254
A33: Impact of Increase in Conception rate
A34: Avg, Milk produced per day | B34: litres | C34: =C11/C22 -> 2.5561967
A35: Increase in milk production due to reduction in inter-calving period per animal | B35: litres | C35: =C34*E31 -> 35.705605
A36: Animals calved successfully | B36: Nos | D36: =C30*$D$20*$C$15*365/$D$31 -> 53587.682 | E36: =(D30*$D$20*$C$15*365/$D$31)+(C30*$D$20*$C$15*($D$31-365)/$D$31) -> 122964.91 | F36: =(E30*$D$20*$C$15*365/$D$31)+(D30*$D$20*$C$15*($D$31-365)/$D$31) -> 227677.46 | G36: =(F30*$D$20*$C$15*365/$D$31)+(E30*$D$20*$C$15*($D$31-365)/$D$31) -> 331162.26 | H36: =(G30*$D$20*$C$15*365/$D$31)+(F30*$D$20*$C$15*($D$31-365)/$D$31) -> 451562.18 | I36: =(H30*$D$20*$C$15*365/$D$31)+(G30*$D$20*$C$15*($D$31-365)/$D$31) -> 545255.84 | J36: =(I30*$D$20*$C$15*365/$D$31)+(H30*$D$20*$C$15*($D$31-365)/$D$31) -> 545737.5 | K36: =(J30*$D$20*$C$15*365/$D$31)+(I30*$D$20*$C$15*($D$31-365)/$D$31) -> 545737.5 | L36: =(K30*$D$20*$C$15*365/$D$31)+(J30*$D$20*$C$15*($D$31-365)/$D$31) -> 545737.5 | ... AB36: =(AA30*$D$20*$C$15*365/$D$31)+(Z30*$D$20*$C$15*($D$31-365)/$D$31) -> 545737.5
A37: Increase in milk production due to reduction in inter-calving period | B37: '000 Tonnes | D37: =D36*$C$35*1.03/1000/1000 -> 1.970782 | E37: =E36*$C$35*1.03/1000/1000 -> 4.5222524 | F37: =F36*$C$35*1.03/1000/1000 -> 8.3732423 | G37: =G36*$C$35*1.03/1000/1000 -> 12.179079 | H37: =H36*$C$35*1.03/1000/1000 -> 16.607 | I37: =I36*$C$35*1.03/1000/1000 -> 20.05275 | J37: =J36*$C$35*1.03/1000/1000 -> 20.070464 | K37: =K36*$C$35*1.03/1000/1000 -> 20.070464 | ... AB37: =AB36*$C$35*1.03/1000/1000 -> 20.070464
A39: Impact of better genetics
A40: Indig. Daughters born | B40: Lakhs | D40: =D36/2/100000*$C$16*Assumptions!$C$10 -> 0.12057228 | E40: =E36/2/100000*$C$16*Assumptions!$C$10 -> 0.27667104 | F40: =F36/2/100000*$C$16*Assumptions!$C$10 -> 0.51227428 | G40: =G36/2/100000*$C$16*Assumptions!$C$10 -> 0.74511508 | H40: =H36/2/100000*$C$16*Assumptions!$C$10 -> 1.0160149 | I40: =I36/2/100000*$C$16*Assumptions!$C$10 -> 1.2268256 | J40: =J36/2/100000*$C$16*Assumptions!$C$10 -> 1.2279094 | K40: =K36/2/100000*$C$16*Assumptions!$C$10 -> 1.2279094 | ... AB40: =AB36/2/100000*$C$16*Assumptions!$C$10 -> 1.2279094
A41: CB Daughters born | B41: Lakhs | D41: =D36/2/100000*$C$16*Assumptions!$C$11 -> 0.12057228 | E41: =E36/2/100000*$C$16*Assumptions!$C$11 -> 0.27667104 | F41: =F36/2/100000*$C$16*Assumptions!$C$11 -> 0.51227428 | G41: =G36/2/100000*$C$16*Assumptions!$C$11 -> 0.74511508 | H41: =H36/2/100000*$C$16*Assumptions!$C$11 -> 1.0160149 | I41: =I36/2/100000*$C$16*Assumptions!$C$11 -> 1.2268256 | J41: =J36/2/100000*$C$16*Assumptions!$C$11 -> 1.2279094 | K41: =K36/2/100000*$C$16*Assumptions!$C$11 -> 1.2279094 | ... AB41: =AB36/2/100000*$C$16*Assumptions!$C$11 -> 1.2279094
A42: WOP Yield | C42: 0.002 | H42: =+C11*(1+$C$42*5) -> 787.4364 | I42: =+H42*(1+$C$42) -> 789.01127 | J42: =+I42*(1+$C$42) -> 790.5893 | K42: =+J42*(1+$C$42) -> 792.17047 | L42: =+K42*(1+$C$42) -> 793.75481 | M42: =+L42*(1+$C$42) -> 795.34232 | N42: =+M42*(1+$C$42) -> 796.93301 | O42: =+N42*(1+$C$42) -> 798.52688 | P42: =+O42*(1+$C$42) -> 800.12393 | ... AB42: =+AA42*(1+$C$42) -> 819.53955
A43: Indig. Daughters calved & in milk | B43: Lakhs | H43: =D40 -> 0.12057228 | I43: =SUM(D40:E40) -> 0.39724332 | J43: =SUM(D40:F40) -> 0.9095176 | K43: =SUM(D40:G40) -> 1.6546327 | L43: =SUM(D40:H40) -> 2.6706476 | M43: =SUM(E40:I40) -> 3.776901 | N43: =SUM(F40:J40) -> 4.7281393 | O43: =SUM(G40:K40) -> 5.4437744 | P43: =SUM(H40:L40) -> 5.9265687 | Q43: =SUM(I40:M40) -> 6.1384631 | R43: =SUM(J40:N40) -> 6.1395469 | S43: =SUM(K40:O40) -> 6.1395469 | ... AB43: =SUM(T40:X40) -> 6.1395469
A44: Year wise Avg. lactation yield of Indig. Daughters | B44: litres | H44: =(1+$C$14*5)*C11 -> 818.622 | I44: =(1+$C$14)*H44 -> 826.80822 | J44: =(1+$C$14)*I44 -> 835.0763 | K44: =(1+$C$14)*J44 -> 843.42707 | L44: =(1+$C$14)*K44 -> 851.86134 | M44: =(1+$C$14)*L44 -> 860.37995 | N44: =(1+$C$14)*M44 -> 868.98375 | O44: =(1+$C$14)*N44 -> 877.67359 | P44: =(1+$C$14)*O44 -> 886.45032 | ... AB44: =(1+$C$14)*AA44 -> 998.87441
A45: Increase in lactation yield of Indig, daughters with respect to base population | B45: litres | H45: =+H44-H42 -> 31.1856 | I45: =+I44-I42 -> 37.796947 | J45: =+J44-J42 -> 44.487007 | K45: =+K44-K42 -> 51.256591 | L45: =+L44-L42 -> 58.106521 | M45: =+M44-M42 -> 65.037625 | N45: =+N44-N42 -> 72.05074 | O45: =+O44-O42 -> 79.146711 | ... AB45: =+AB44-AB42 -> 179.33486
A47: Incrmntl Milk production Matrix
A48: 1st lactation | B48: litres | H48: =H$45*D$40*100000 -> 376011.9 | I48: =I$45*E$40*100000 -> 1045732.1 | J48: =J$45*F$40*100000 -> 2278955 | K48: =K$45*G$40*100000 -> 3819205.9 | L48: =L$45*H$40*100000 -> 5903709.2 | M48: =M$45*I$40*100000 -> 7978982.6 | N48: =N$45*J$40*100000 -> 8847177.9 | O48: =O$45*K$40*100000 -> 9718498.8 | ... AB48: =AB$45*X$40*100000 -> 22020696
...

Sheet NDSP Bull, SS & Non-NDSP AI
B1: Unit | C1: 2011-12 | D1: 2012-13 | E1: 2013-14 | F1: 2014-15 | G1: 2015-16 | H1: 2016-17 | I1: 2017-18 | J1: 2018-19 | K1: 2019-20 | L1: 2020-21 | M1: 2021-22 | N1: 2022-23 | O1: 2023-24 | P1: 2024-25 | Q1: 2025-26 | R1: 2026-27 | S1: 2027-28 | T1: 2028-29 | U1: 2029-30 | V1: 2030-31 | W1: 2031-32 | X1: 2032-33 | Y1: 2033-34 | Z1: 2034-35 | AA1: 2035-36 | AB1: 2036-37 | AC1: 2037-38
A2: Highlights of Semen Production
A3: 28 Semen Stations would be strenghened and 2 new semen station would be established
A4: Semen doses produced by them would be available for sale across the country, incl. 3000 AI centres that are getting established under NDSP.
A5: Semen doses produced by semen stations funded by NDSP would lead to higher conception rate and also the daughters born from such inseminations would have higher genetic potential for milk production
A6: All semen doses produced by these semen stations would be from bulls produced by bull production programmes funded by NDSP
A7: Increase in conception rate leads to a decrease in intercalving period and thus there is an increse in annual milk production.
A8: All semen doses produced are used in AI services in the same year, neglecting wastage
A9: Strengethening and establishment of semen stations lead to improvement in quality of semen production and increase in semen production.
A10: For calculating the benefits due to these 28 existing & 2 new semen stations (which use increasingly more number of higher genetic bulls produced by NDSP bull production programmes), we would have considered only semen doses being used by non-NDSP AI centres. Semen doses produced by these semen stations and used by NDSP AI centres have already been accounted in the sheet on "AI Delivery system".
A11: The project period has been assumed to be till 2036-37 for which benefits have been accounted, though NDSP would be funded in the first phase till 2016-17. The infrastructure created with respect to AI delivery, Semen stations and bull production would be available for a longer period of time.
A13: Assumptions | B13: Unit | C13: Indig. Cattle | D13: CB Cattle | E13: Buffaloes
A14: Avg. lactation yield | B14: litres | C14: =Assumptions!C3 -> 779.64 | D14: =Assumptions!D3 -> 2507.185 | E14: =Assumptions!E3 -> 1668.415
A15: Age at first calving | B15: years | C15: =Assumptions!C4 -> 4 | D15: =Assumptions!D4 -> 3 | E15: =Assumptions!E4 -> 4
A16: No. of lactations per animal | B16: Nos | C16: =Assumptions!C5 -> 5 | D16: =Assumptions!D5 -> 5 | E16: =Assumptions!E5 -> 5
A17: Anuual Increase in milk yield | B17: % | C17: =Assumptions!C6 -> 0.01 | D17: =Assumptions!D6 -> 0.01 | E17: =Assumptions!E6 -> 0.01
A18: Calving rate over pregnancy | C18: =Assumptions!C7 -> 0.9 | D18: =Assumptions!D7 -> 0.9 | E18: =Assumptions!E7 -> 0.9
A19: female calves alive rate | C19: =Assumptions!C8 -> 0.9 | D19: =Assumptions!D8 -> 0.9 | E19: =Assumptions!E8 -> 0.9
A20: Breed-wise Composition of AI done | B20: % | C20: =Assumptions!C9 -> 0.2 | D20: =Assumptions!D9 -> 0.5 | E20: =Assumptions!E9 -> 0.3
C22: Without NDSP | D22: With NDSP
A23: Conception rate | C23: =Assumptions!B14 -> 0.35 | D23: =Assumptions!C15 -> 0.38
A24: Lactation Period | B24: days | C24: =+Assumptions!C26 -> 305 | D24: =+Assumptions!D26 -> 305 | E24: =+Assumptions!E26 -> 305
A25: Semen doses from New Semen Stations (2) | B25: lakh Doses | C25: ='Semen production'!G40 -> 0 | D25: ='Semen production'!H40 -> 10 | E25: ='Semen production'!I40 -> 31.9576 | F25: ='Semen production'!J40 -> 56 | G25: ='Semen production'!K40 -> 76.983839 | H25: ='Semen production'!L40 -> 90 | I25: =58.8+41.5 -> 100.3 | J25: =72.58+58.8 -> 131.38 | K25: =89.07+72.58 -> 161.65 | L25: =98+89.07 -> 187.07 | M25: =98+98 -> 196 | N25: =98+98 -> 196 | O25: =98+98 -> 196 | P25: =98+98 -> 196 | Q25: =98+98 -> 196 | R25: =98+98 -> 196 | S25: =98+98 -> 196 | T25: =98+98 -> 196 | ... AB25: =98+98 -> 196
A26: Semen doses from strengthened SS(28) | B26: lakh Doses | C26: ='Semen production'!G31 -> 592.115 | D26: ='Semen production'!H31 -> 652.97 | E26: ='Semen production'!I31 -> 722.435 | F26: ='Semen production'!J31 -> 789.8 | G26: ='Semen production'!K31 -> 848.4 | H26: ='Semen production'!L31 -> 910 | I26: 910 | J26: 910 | K26: 910 | L26: 910 | M26: 910 | N26: 910 | O26: 910 | P26: 910 | Q26: 910 | R26: 910 | S26: 910 | T26: 910 | U26: 910 | V26: 910 | W26: 910 | X26: 910 | Y26: 910 | Z26: 910 | AA26: 910 | AB26: 910
A27: Semen production under NDSP semen station | B27: lakh Doses | C27: =C25+C26 -> 592.115 | D27: =D25+D26 -> 662.97 | E27: =E25+E26 -> 754.3926 | F27: =F25+F26 -> 845.8 | G27: =G25+G26 -> 925.38384 | H27: =H25+H26 -> 1000 | I27: =I26+I25 -> 1010.3 | J27: =J26+J25 -> 1041.38 | K27: =K26+K25 -> 1071.65 | L27: =L26+L25 -> 1097.07 | M27: =M26+M25 -> 1106 | N27: =N26+N25 -> 1106 | O27: =O26+O25 -> 1106 | P27: =P26+P25 -> 1106 | ... AB27: =AB26+AB25 -> 1106
A29: Semen produced from NDSP bulls | B29: lakh Doses | C29: ='Bull no. & Semen Production'!D70 -> 8.94 | D29: ='Bull no. & Semen Production'!E70 -> 92.416768 | E29: ='Bull no. & Semen Production'!F70 -> 201.48483 | F29: ='Bull no. & Semen Production'!G70 -> 350.22553 | G29: ='Bull no. & Semen Production'!H70 -> 551.98141 | H29: ='Bull no. & Semen Production'!I70 -> 727.85423 | I29: =H29 -> 727.85423 | J29: =I29 -> 727.85423 | K29: =J29 -> 727.85423 | L29: =K29 -> 727.85423 | M29: =L29 -> 727.85423 | N29: =M29 -> 727.85423 | O29: =N29 -> 727.85423 | P29: =O29 -> 727.85423 | ... AB29: =AA29 -> 727.85423
A30: Semen produced in NDSP semen stations and from NDSP bulls | B30: lakh Doses | C30: =MIN(C29,C27) -> 8.94 | D30: =MIN(D29,D27) -> 92.416768 | E30: =MIN(E29,E27) -> 201.48483 | F30: =MIN(F29,F27) -> 350.22553 | G30: =MIN(G29,G27) -> 551.98141 | H30: =MIN(H29,H27) -> 727.85423 | I30: =MIN(I29,I27) -> 727.85423 | J30: =MIN(J29,J27) -> 727.85423 | ... AB30: =MIN(AB29,AB27) -> 727.85423
A31: Semen produced by non-NDSP semen stations but from NDSP bulls | B31: lakh Doses | C31: =C29-C30 -> 0 | D31: =D29-D30 -> 0 | E31: =E29-E30 -> 0 | F31: =F29-F30 -> 0 | G31: =G29-G30 -> 0 | H31: =H29-H30 -> 0 | I31: =I29-I30 -> 0 | J31: =J29-J30 -> 0 | ... AB31: =AB29-AB30 -> 0
A33: AI done from these semen doses | B33: lakh Doses | C33: =C30 -> 8.94 | D33: =D30 -> 92.416768 | E33: =E30 -> 201.48483 | F33: =F30 -> 350.22553 | G33: =G30 -> 551.98141 | H33: =H30 -> 727.85423 | I33: =I30 -> 727.85423 | J33: =J30 -> 727.85423 | ... AB33: =AB30 -> 727.85423
A34: AI done by NDSP AI centres | B34: lakh Doses | C34: ='NDSP Bull,SS,AI'!C25 -> 3.8 | D34: ='NDSP Bull,SS,AI'!D25 -> 8.7 | E34: ='NDSP Bull,SS,AI'!E25 -> 16.1 | F34: ='NDSP Bull,SS,AI'!F25 -> 23.4 | G34: ='NDSP Bull,SS,AI'!G25 -> 31.9 | H34: ='NDSP Bull,SS,AI'!H25 -> 38.5 | I34: ='NDSP Bull,SS,AI'!I25 -> 38.5 | J34: ='NDSP Bull,SS,AI'!J25 -> 38.5 | ... AB34: ='NDSP Bull,SS,AI'!AB25 -> 38.5
A35: AI done by non-NDSP AI centres | B35: lakh Doses | C35: =C33-C34 -> 5.14 | D35: =D33-D34 -> 83.716768 | E35: =E33-E34 -> 185.38483 | F35: =F33-F34 -> 326.82553 | G35: =G33-G34 -> 520.08141 | H35: =H33-H34 -> 689.35423 | I35: =I33-I34 -> 689.35423 | J35: =J33-J34 -> 689.35423 | ... AB35: =AB33-AB34 -> 689.35423
A37: AI Nos. | B37: Nos. | C37: =C35*100000 -> 514000 | D37: =D35*100000 -> 8371676.8 | E37: =E35*100000 -> 18538483 | F37: =F35*100000 -> 32682553 | G37: =G35*100000 -> 52008141 | H37: =H35*100000 -> 68935423 | I37: =I35*100000 -> 68935423 | J37: =J35*100000 -> 68935423 | ... AB37: =AB35*100000 -> 68935423
C39: Without NDSP | D39: With NDSP | E39: Difference
A40: INDIGENOUS COWS
A41: AI Nos. | B41: Nos. | C41: =C37*$C$20 -> 102800 | D41: =D37*$C$20 -> 1674335.4 | E41: =E37*$C$20 -> 3707696.6 | F41: =F37*$C$20 -> 6536510.6 | G41: =G37*$C$20 -> 10401628 | H41: =H37*$C$20 -> 13787085 | I41: =I37*$C$20 -> 13787085 | J41: =J37*$C$20 -> 13787085 | ... AB41: =AB37*$C$20 -> 13787085
A42: Inter-Calving period | C42: =280+60+((1/C23)-1)*22 -> 380.85714 | D42: =280+60+((1/D23)-1)*22 -> 375.89474 | E42: =C42-D42 -> 4.962406
A44: Impact of Increase in Conception rate
A45: Avg, Milk produced per day | B45: litres | C45: =C14/C24 -> 2.5561967
A46: Increase in milk production due to reduction in inter-calving period per animal | B46: litres | C46: =C45*E42 -> 12.684886
A47: Animals calved successfully | B47: Nos | D47: =C41*$D$23*$C$18*365/$D$42 -> 34138.61 | E47: =(D41*$D$23*$C$18*365/$D$42)+(C41*$D$23*$C$18*($D$42-365)/$D$42) -> 557045.09 | F47: =(E41*$D$23*$C$18*365/$D$42)+(D41*$D$23*$C$18*($D$42-365)/$D$42) -> 1247876.9 | G47: =(F41*$D$23*$C$18*365/$D$42)+(E41*$D$23*$C$18*($D$42-365)/$D$42) -> 2207446.4 | H47: =(G41*$D$23*$C$18*365/$D$42)+(F41*$D$23*$C$18*($D$42-365)/$D$42) -> 3519044.4 | I47: =(H41*$D$23*$C$18*365/$D$42)+(G41*$D$23*$C$18*($D$42-365)/$D$42) -> 4681625.1 | J47: =(I41*$D$23*$C$18*365/$D$42)+(H41*$D$23*$C$18*($D$42-365)/$D$42) -> 4715182.9 | K47: =(J41*$D$23*$C$18*365/$D$42)+(I41*$D$23*$C$18*($D$42-365)/$D$42) -> 4715182.9 | L47: =(K41*$D$23*$C$18*365/$D$42)+(J41*$D$23*$C$18*($D$42-365)/$D$42) -> 4715182.9 | ... AB47: =(AA41*$D$23*$C$18*365/$D$42)+(Z41*$D$23*$C$18*($D$42-365)/$D$42) -> 4715182.9
...

Sheet NDSP-Bull & Non-NDSP SS,AI
B1: Unit | C1: 2011-12 | D1: 2012-13 | E1: 2013-14 | F1: 2014-15 | G1: 2015-16 | H1: 2016-17 | I1: 2017-18 | J1: 2018-19 | K1: 2019-20 | L1: 2020-21 | M1: 2021-22 | N1: 2022-23 | O1: 2023-24 | P1: 2024-25 | Q1: 2025-26 | R1: 2026-27 | S1: 2027-28 | T1: 2028-29 | U1: 2029-30 | V1: 2030-31 | W1: 2031-32 | X1: 2032-33 | Y1: 2033-34 | Z1: 2034-35 | AA1: 2035-36 | AB1: 2036-37 | AC1: 2037-38
A2: Highlights of Bull Production
A3: Bulls produced by these projects would be available for sale to all semen stations incl. the ones funded by NDSP
A4: Semen from genetically superior quality bulls would have an impact on the increase in conception rate and birth of daughters with higher genetic potential for milk production
A5: Increase in conception rate leads to a decrease in intercalving period and thus there is an increse in annual milk production.
A6: All semen doses produced are used in AI services in the same year, neglecting wastage
A7: For calculating benefits due to these bull production programmes, we would have considered only semen doses produced by bulls stationed in semen stations not funded by NDSP. Semen doses produced by bulls stationed in semen stations funded by NDSP and used by AI centres funded by NDSP have already been accounted in the sheets on "AI Delivery system" and "FSP".
A8: The project period has been assumed to be till 2036-37 for which benefits have been accounted, though NDSP would be funded in the first phase till 2016-17. The infrastructure created with respect to AI delivery, Semen stations and bull production would be available for a longer period of time.
A11: Assumptions | B11: Unit | C11: Indig. Cattle | D11: CB Cattle | E11: Buffaloes
A12: Avg. lactation yield | B12: litres | C12: =Assumptions!C3 -> 779.64 | D12: =Assumptions!D3 -> 2507.185 | E12: =Assumptions!E3 -> 1668.415
A13: Age at first calving | B13: years | C13: =Assumptions!C4 -> 4 | D13: =Assumptions!D4 -> 3 | E13: =Assumptions!E4 -> 4
A14: No. of lactations per animal | B14: Nos | C14: =Assumptions!C5 -> 5 | D14: =Assumptions!D5 -> 5 | E14: =Assumptions!E5 -> 5
A15: Anuual Increase in milk yield | B15: % | C15: =Assumptions!C6 -> 0.01 | D15: =Assumptions!D6 -> 0.01 | E15: =Assumptions!E6 -> 0.01
A16: Calving rate over pregnancy | C16: =Assumptions!C7 -> 0.9 | D16: =Assumptions!D7 -> 0.9 | E16: =Assumptions!E7 -> 0.9
A17: female calves alive rate | C17: =Assumptions!C8 -> 0.9 | D17: =Assumptions!D8 -> 0.9 | E17: =Assumptions!E8 -> 0.9
A18: Breed-wise Composition of AI done | B18: % | C18: =Assumptions!C9 -> 0.2 | D18: =Assumptions!D9 -> 0.5 | E18: =Assumptions!E9 -> 0.3
C20: Without NDSP | D20: With NDSP
A21: Conception rate | C21: =Assumptions!B14 -> 0.35 | D21: =Assumptions!C16 -> 0.36
A23: Semen produced from NDSP bulls | B23: lakh Doses | C23: ='Bull no. & Semen Production'!D70 -> 8.94 | D23: ='Bull no. & Semen Production'!E70 -> 92.416768 | E23: ='Bull no. & Semen Production'!F70 -> 201.48483 | F23: ='Bull no. & Semen Production'!G70 -> 350.22553 | G23: ='Bull no. & Semen Production'!H70 -> 551.98141 | H23: ='Bull no. & Semen Production'!I70 -> 727.85423 | I23: =H23 -> 727.85423 | J23: =I23 -> 727.85423 | K23: =J23 -> 727.85423 | L23: =K23 -> 727.85423 | M23: =L23 -> 727.85423 | N23: =M23 -> 727.85423 | O23: =N23 -> 727.85423 | P23: =O23 -> 727.85423 | ... AB23: =AA23 -> 727.85423
A24: Semen produced from NDSP bulls in NDSP assisted semen stations | B24: lakh Doses | C24: ='NDSP Bull, SS & Non-NDSP AI'!C30 -> 8.94 | D24: ='NDSP Bull, SS & Non-NDSP AI'!D30 -> 92.416768 | E24: ='NDSP Bull, SS & Non-NDSP AI'!E30 -> 201.48483 | F24: ='NDSP Bull, SS & Non-NDSP AI'!F30 -> 350.22553 | G24: ='NDSP Bull, SS & Non-NDSP AI'!G30 -> 551.98141 | H24: ='NDSP Bull, SS & Non-NDSP AI'!H30 -> 727.85423 | I24: ='NDSP Bull, SS & Non-NDSP AI'!I30 -> 727.85423 | J24: ='NDSP Bull, SS & Non-NDSP AI'!J30 -> 727.85423 | ... AB24: ='NDSP Bull, SS & Non-NDSP AI'!AB30 -> 727.85423
A25: Semen produced by non-NDSP semen stations but from NDSP bulls | B25: lakh Doses | C25: =C23-C24 -> 0 | D25: =D23-D24 -> 0 | E25: =E23-E24 -> 0 | F25: =F23-F24 -> 0 | G25: =G23-G24 -> 0 | H25: =H23-H24 -> 0 | I25: =I23-I24 -> 0 | J25: =J23-J24 -> 0 | ... AB25: =AB23-AB24 -> 0
A27: AI done from these semen doses | B27: lakhs | C27: =C25 -> 0 | D27: =D25 -> 0 | E27: =E25 -> 0 | F27: =F25 -> 0 | G27: =G25 -> 0 | H27: =H25 -> 0 | I27: =I25 -> 0 | J27: =J25 -> 0 | ... AB27: =AB25 -> 0
A28: AI Nos. | B28: Nos. | C28: =C27*100000 -> 0 | D28: =D27*100000 -> 0 | E28: =E27*100000 -> 0 | F28: =F27*100000 -> 0 | G28: =G27*100000 -> 0 | H28: =H27*100000 -> 0 | I28: =I27*100000 -> 0 | J28: =J27*100000 -> 0 | ... AB28: =AB27*100000 -> 0
C30: Without NDSP | D30: With NDSP | E30: Difference
A31: INDIGENOUS COWS
A32: AI Nos. | B32: Nos. | C32: =C28*$C$18 -> 0 | D32: =D28*$C$18 -> 0 | E32: =E28*$C$18 -> 0 | F32: =F28*$C$18 -> 0 | G32: =G28*$C$18 -> 0 | H32: =H28*$C$18 -> 0 | I32: =I28*$C$18 -> 0 | J32: =J28*$C$18 -> 0 | ... AB32: =AB28*$C$18 -> 0
A33: Inter-Calving period | C33: =280+60+((1/C21)-1)*22 -> 380.85714 | D33: =280+60+((1/D21)-1)*22 -> 379.11111 | E33: =C33-D33 -> 1.7460317
A35: Impact of Increase in Conception rate
A36: Avg, Milk produced per day | B36: litres | C36: =C12/305 -> 2.5561967
A37: Increase in milk production due to reduction in inter-calving period per animal | B37: litres | C37: =C36*E33 -> 4.4632006
A38: Animals calved successfully | B38: Nos | D38: =C32*$D$21*$C$16*365/$D$33 -> 0 | E38: =(D32*$D$21*$C$16*365/$D$33)+(C32*$D$21*$C$16*($D$33-365)/$D$33) -> 0 | F38: =(E32*$D$21*$C$16*365/$D$33)+(D32*$D$21*$C$16*($D$33-365)/$D$33) -> 0 | G38: =(F32*$D$21*$C$16*365/$D$33)+(E32*$D$21*$C$16*($D$33-365)/$D$33) -> 0 | H38: =(G32*$D$21*$C$16*365/$D$33)+(F32*$D$21*$C$16*($D$33-365)/$D$33) -> 0 | I38: =(H32*$D$21*$C$16*365/$D$33)+(G32*$D$21*$C$16*($D$33-365)/$D$33) -> 0 | J38: =(I32*$D$21*$C$16*365/$D$33)+(H32*$D$21*$C$16*($D$33-365)/$D$33) -> 0 | K38: =(J32*$D$21*$C$16*365/$D$33)+(I32*$D$21*$C$16*($D$33-365)/$D$33) -> 0 | L38: =(K32*$D$21*$C$16*365/$D$33)+(J32*$D$21*$C$16*($D$33-365)/$D$33) -> 0 | ... AB38: =(AA32*$D$21*$C$16*365/$D$33)+(Z32*$D$21*$C$16*($D$33-365)/$D$33) -> 0
A39: Increase in milk production due to reduction in inter-calving period | B39: '000 Tonnes | D39: =D38*$C$37*1.03/1000/1000 -> 0 | E39: =E38*$C$37*1.03/1000/1000 -> 0 | F39: =F38*$C$37*1.03/1000/1000 -> 0 | G39: =G38*$C$37*1.03/1000/1000 -> 0 | H39: =H38*$C$37*1.03/1000/1000 -> 0 | I39: =I38*$C$37*1.03/1000/1000 -> 0 | J39: =J38*$C$37*1.03/1000/1000 -> 0 | K39: =K38*$C$37*1.03/1000/1000 -> 0 | ... AB39: =AB38*$C$37*1.03/1000/1000 -> 0
A41: Impact of better genetics
A42: Indig. Daughters born | B42: Lakhs | D42: =D38/2/100000*$C$17*Assumptions!$C$10 -> 0 | E42: =E38/2/100000*$C$17*Assumptions!$C$10 -> 0 | F42: =F38/2/100000*$C$17*Assumptions!$C$10 -> 0 | G42: =G38/2/100000*$C$17*Assumptions!$C$10 -> 0 | H42: =H38/2/100000*$C$17*Assumptions!$C$10 -> 0 | I42: =I38/2/100000*$C$17*Assumptions!$C$10 -> 0 | J42: =J38/2/100000*$C$17*Assumptions!$C$10 -> 0 | K42: =K38/2/100000*$C$17*Assumptions!$C$10 -> 0 | ... AB42: =AB38/2/100000*$C$17*Assumptions!$C$10 -> 0
A43: CB Daughters born | B43: Lakhs | D43: =D38/2/100000*$C$17*Assumptions!$C$11 -> 0 | E43: =E38/2/100000*$C$17*Assumptions!$C$11 -> 0 | F43: =F38/2/100000*$C$17*Assumptions!$C$11 -> 0 | G43: =G38/2/100000*$C$17*Assumptions!$C$11 -> 0 | H43: =H38/2/100000*$C$17*Assumptions!$C$11 -> 0 | I43: =I38/2/100000*$C$17*Assumptions!$C$11 -> 0 | J43: =J38/2/100000*$C$17*Assumptions!$C$11 -> 0 | K43: =K38/2/100000*$C$17*Assumptions!$C$11 -> 0 | ... AB43: =AB38/2/100000*$C$17*Assumptions!$C$11 -> 0
A45: Indig. Daughters calved & in milk | B45: Lakhs | H45: =D42 -> 0 | I45: =SUM(D42:E42) -> 0 | J45: =SUM(D42:F42) -> 0 | K45: =SUM(D42:G42) -> 0 | L45: =SUM(D42:H42) -> 0 | M45: =SUM(E42:I42) -> 0 | N45: =SUM(F42:J42) -> 0 | O45: =SUM(G42:K42) -> 0 | P45: =SUM(H42:L42) -> 0 | Q45: =SUM(I42:M42) -> 0 | R45: =SUM(J42:N42) -> 0 | S45: =SUM(K42:O42) -> 0 | ... AB45: =SUM(T42:X42) -> 0
A46: Year wise Avg. lactation yield of Indig. Daughters | B46: litres | H46: =(1+$C$15*5)*C12 -> 818.622 | I46: =(1+$C$15)*H46 -> 826.80822 | J46: =(1+$C$15)*I46 -> 835.0763 | K46: =(1+$C$15)*J46 -> 843.42707 | L46: =(1+$C$15)*K46 -> 851.86134 | M46: =(1+$C$15)*L46 -> 860.37995 | N46: =(1+$C$15)*M46 -> 868.98375 | O46: =(1+$C$15)*N46 -> 877.67359 | P46: =(1+$C$15)*O46 -> 886.45032 | ... AB46: =(1+$C$15)*AA46 -> 998.87441
A47: Increase in lactation yield of Indig, daughters with respect to base population | B47: litres | H47: =H46-$C$12 -> 38.982 | I47: =I46-$C$12 -> 47.16822 | J47: =J46-$C$12 -> 55.436302 | K47: =K46-$C$12 -> 63.787065 | L47: =L46-$C$12 -> 72.221336 | M47: =M46-$C$12 -> 80.739949 | N47: =N46-$C$12 -> 89.343749 | O47: =O46-$C$12 -> 98.033586 | ... AB47: =AB46-$C$12 -> 219.23441
A49: Incrmntl Milk production Matrix
A50: 1st lactation | B50: litres | H50: =H$47*D$42*100000 -> 0 | I50: =I$47*E$42*100000 -> 0 | J50: =J$47*F$42*100000 -> 0 | K50: =K$47*G$42*100000 -> 0 | L50: =L$47*H$42*100000 -> 0 | M50: =M$47*I$42*100000 -> 0 | N50: =N$47*J$42*100000 -> 0 | O50: =O$47*K$42*100000 -> 0 | ... AB50: =AB$47*X$42*100000 -> 0
...

Sheet NDSP - Bull & Semen
A1: Programme wise Bulls produced from planned Bull Production Programmes
A2: Sno | B2: PT Project | C2: Breed | D2: 09-10 | E2: 10-11 | F2: 11-12 | G2: 12-13 | H2: 13-14 | I2: 14-15 | J2: 15-16 | K2: 16-17
A3: 1 | B3: KMF PT | C3: Exotic HF | D3: 0 | E3: 0 | F3: 12.24 | G3: 23.256 | H3: 34.272 | I3: 45.288 | J3: 62.1504 | K3: =66.3984 -> 66.3984
A4: 2 | B4: SAG PT | C4: CB HF | D4: 0 | E4: 14 | F4: 14 | G4: 22.3272 | H4: 29.82168 | I4: 36.566712 | J4: 55.338041 | K4: 71.150317
A5: 3 | B5: SAG PT | C5: Murrah | D5: 0 | E5: 12 | F5: 14 | G5: 21.9996 | H5: 29.19924 | I5: 35.678916 | J5: 41.510624 | K5: 55.436362
A6: 4 | B6: Banas Union PT | C6: Mehsana | D6: 0 | E6: 0 | F6: 6 | G6: 11.4 | H6: 16.26 | I6: 20.634 | J6: 24.5706 | K6: 24.28254
A7: 5 | B7: Mehsana Union PT | C7: Mehsana | D7: 0 | E7: 0 | F7: 6 | G7: 11.76 | H7: 16.944 | I7: 21.6096 | J7: 25.80864 | K7: 25.341276
A8: 6 | B8: UP Meerut PT | C8: Murrah | D8: 0 | E8: 0 | F8: 8.4 | G8: 15.96 | H8: 22.764 | I8: 28.8876 | J8: 34.39884 | K8: 35.45
A9: 7 | B9: Haryana PT | C9: Murrah | E9: 0 | F9: 0 | G9: 0 | H9: 6 | I9: 11 | J9: 16 | K9: 22
A10: 8 | B10: TCMPF PT | C10: CB Jersey | E10: 0 | F10: 0 | G10: 11.76 | H10: 24.024 | I10: 35.0616 | J10: 44.99544 | K10: 66.636696
A11: 9 | B11: Punjab PT | C11: Murrah | F11: 0 | G11: 0 | H11: 0 | I11: 17 | J11: 32 | K11: 45
A12: 11 | B12: Rathi breed | C12: Rathi | E12: 0 | F12: 0 | G12: 11.25 | H12: 16.875 | I12: 19.125 | J12: 20 | K12: 20
A13: 12 | B13: Tharparkar breed | C13: Tharparkar | E13: 0 | F13: 0 | G13: 0 | H13: 11 | I13: 17 | J13: 19 | K13: 20
A14: 13 | B14: Kankrej breed | C14: Kankrej | E14: 0 | F14: 0 | G14: 11.25 | H14: 16.875 | I14: 19.125 | J14: 20 | K14: 20
A15: 14 | B15: Gir | C15: Gir | G15: 0 | H15: 0 | I15: 11 | J15: 17 | K15: 19
A16: 15 | B16: Jaffarabadi | C16: Jaffarabadi | G16: 0 | H16: 0 | I16: 11 | J16: 17 | K16: 19
A17: 16 | B17: HF Calf rearing station, Jallandhar | C17: Exotic HF | F17: 0 | G17: 30 | H17: 35 | I17: 40 | J17: 45 | K17: 50
A18: 17 | B18: Imports | C18: Exotic HF | F18: 0 | G18: 0 | H18: 0 | I18: 50 | J18: 0 | K18: 50
A19: 18 | B19: Imports | C19: Exotic Jersey | F19: 100 | G19: 100 | H19: 0 | I19: 50 | J19: 0 | K19: 50
A20: Total (NDSP) | D20: =SUM(D3:D19) -> 0 | E20: =SUM(E3:E19) -> 26 | F20: =SUM(F3:F19) -> 160.64 | G20: =SUM(G3:G19) -> 270.9628 | H20: =SUM(H3:H19) -> 259.03492 | I20: =SUM(I3:I19) -> 468.97643 | J20: =SUM(J3:J19) -> 474.77259 | K20: =SUM(K3:K19) -> 659.69559
C22: Breed-wise Bulls produced
C23: Breeds | D23: 09-10 | E23: 10-11 | F23: 11-12 | G23: 12-13 | H23: 13-14 | I23: 14-15 | J23: 15-16 | K23: 16-17
C24: Exotic HF | D24: =SUMIF($C$3:$C$19,$C24,D$3:D$19) -> 0 | E24: =SUMIF($C$3:$C$19,$C24,E$3:E$19) -> 0 | F24: =SUMIF($C$3:$C$19,$C24,F$3:F$19) -> 12.24 | G24: =SUMIF($C$3:$C$19,$C24,G$3:G$19) -> 53.256 | H24: =SUMIF($C$3:$C$19,$C24,H$3:H$19) -> 69.272 | I24: =SUMIF($C$3:$C$19,$C24,I$3:I$19) -> 135.288 | J24: =SUMIF($C$3:$C$19,$C24,J$3:J$19) -> 107.1504 | K24: =SUMIF($C$3:$C$19,$C24,K$3:K$19) -> 166.3984
C25: Exotic Jersey | D25: =SUMIF($C$3:$C$19,$C25,D$3:D$19) -> 0 | E25: =SUMIF($C$3:$C$19,$C25,E$3:E$19) -> 0 | F25: =SUMIF($C$3:$C$19,$C25,F$3:F$19) -> 100 | G25: =SUMIF($C$3:$C$19,$C25,G$3:G$19) -> 100 | H25: =SUMIF($C$3:$C$19,$C25,H$3:H$19) -> 0 | I25: =SUMIF($C$3:$C$19,$C25,I$3:I$19) -> 50 | J25: =SUMIF($C$3:$C$19,$C25,J$3:J$19) -> 0 | K25: =SUMIF($C$3:$C$19,$C25,K$3:K$19) -> 50
C26: CB HF | D26: =SUMIF($C$3:$C$19,$C26,D$3:D$19) -> 0 | E26: =SUMIF($C$3:$C$19,$C26,E$3:E$19) -> 14 | F26: =SUMIF($C$3:$C$19,$C26,F$3:F$19) -> 14 | G26: =SUMIF($C$3:$C$19,$C26,G$3:G$19) -> 22.3272 | H26: =SUMIF($C$3:$C$19,$C26,H$3:H$19) -> 29.82168 | I26: =SUMIF($C$3:$C$19,$C26,I$3:I$19) -> 36.566712 | J26: =SUMIF($C$3:$C$19,$C26,J$3:J$19) -> 55.338041 | K26: =SUMIF($C$3:$C$19,$C26,K$3:K$19) -> 71.150317
C27: CB Jersey | D27: =SUMIF($C$3:$C$19,$C27,D$3:D$19) -> 0 | E27: =SUMIF($C$3:$C$19,$C27,E$3:E$19) -> 0 | F27: =SUMIF($C$3:$C$19,$C27,F$3:F$19) -> 0 | G27: =SUMIF($C$3:$C$19,$C27,G$3:G$19) -> 11.76 | H27: =SUMIF($C$3:$C$19,$C27,H$3:H$19) -> 24.024 | I27: =SUMIF($C$3:$C$19,$C27,I$3:I$19) -> 35.0616 | J27: =SUMIF($C$3:$C$19,$C27,J$3:J$19) -> 44.99544 | K27: =SUMIF($C$3:$C$19,$C27,K$3:K$19) -> 66.636696
C28: Murrah | D28: =SUMIF($C$3:$C$19,$C28,D$3:D$19) -> 0 | E28: =SUMIF($C$3:$C$19,$C28,E$3:E$19) -> 12 | F28: =SUMIF($C$3:$C$19,$C28,F$3:F$19) -> 22.4 | G28: =SUMIF($C$3:$C$19,$C28,G$3:G$19) -> 37.9596 | H28: =SUMIF($C$3:$C$19,$C28,H$3:H$19) -> 57.96324 | I28: =SUMIF($C$3:$C$19,$C28,I$3:I$19) -> 92.566516 | J28: =SUMIF($C$3:$C$19,$C28,J$3:J$19) -> 123.90946 | K28: =SUMIF($C$3:$C$19,$C28,K$3:K$19) -> 157.88636
C29: Mehsana | D29: =SUMIF($C$3:$C$19,$C29,D$3:D$19) -> 0 | E29: =SUMIF($C$3:$C$19,$C29,E$3:E$19) -> 0 | F29: =SUMIF($C$3:$C$19,$C29,F$3:F$19) -> 12 | G29: =SUMIF($C$3:$C$19,$C29,G$3:G$19) -> 23.16 | H29: =SUMIF($C$3:$C$19,$C29,H$3:H$19) -> 33.204 | I29: =SUMIF($C$3:$C$19,$C29,I$3:I$19) -> 42.2436 | J29: =SUMIF($C$3:$C$19,$C29,J$3:J$19) -> 50.37924 | K29: =SUMIF($C$3:$C$19,$C29,K$3:K$19) -> 49.623816
C30: Indigenous | D30: =SUM(D12:D16) -> 0 | E30: =SUM(E12:E16) -> 0 | F30: =SUM(F12:F16) -> 0 | G30: =SUM(G12:G16) -> 22.5 | H30: =SUM(H12:H16) -> 44.75 | I30: =SUM(I12:I16) -> 77.25 | J30: =SUM(J12:J16) -> 93 | K30: =SUM(K12:K16) -> 98
C31: Total (NDSP) | D31: =SUM(D24:D30) -> 0 | E31: =SUM(E24:E30) -> 26 | F31: =SUM(F24:F30) -> 160.64 | G31: =SUM(G24:G30) -> 270.9628 | H31: =SUM(H24:H30) -> 259.03492 | I31: =SUM(I24:I30) -> 468.97643 | J31: =SUM(J24:J30) -> 474.77259 | K31: =SUM(K24:K30) -> 659.69559
C36: Breed-wise Bulls under collection (produced from NDDB Bull production Programmes)
C37: Breeds | D37: 09-10 | E37: 10-11 | F37: 11-12 | G37: 12-13 | H37: 13-14 | I37: 14-15 | J37: 15-16 | K37: 16-17 | L37: Semen/ bull
C38: Exotic HF | D38: =D24 -> 0 | E38: =SUM($D24:E24) -> 0 | F38: =SUM($D24:F24) -> 12.24 | G38: =SUM(E24:G24)+D24/3 -> 65.496 | H38: =SUM(F24:H24)+E24/3 -> 134.768 | I38: =SUM(G24:I24)+F24/3 -> 261.896 | J38: =SUM(H24:J24)+G24/3 -> 329.4624 | K38: =SUM(I24:K24)+H24/3 -> 431.92747 | L38: 35000
C39: Exotic Jersey | D39: =D25 -> 0 | E39: =SUM($D25:E25) -> 0 | F39: =SUM($D25:F25) -> 100 | G39: =SUM(E25:G25)+D25/3 -> 200 | H39: =SUM(F25:H25)+E25/3 -> 200 | I39: =SUM(G25:I25)+F25/3 -> 183.33333 | J39: =SUM(H25:J25)+G25/3 -> 83.333333 | K39: =SUM(I25:K25)+H25/3 -> 100 | L39: 35000
C40: CB HF | D40: =D26 -> 0 | E40: =SUM($D26:E26) -> 14 | F40: =SUM($D26:F26) -> 28 | G40: =SUM(E26:G26)+D26/3 -> 50.3272 | H40: =SUM(F26:H26)+E26/3 -> 70.815547 | I40: =SUM(G26:I26)+F26/3 -> 93.382259 | J40: =SUM(H26:J26)+G26/3 -> 129.16883 | K40: =SUM(I26:K26)+H26/3 -> 172.99563 | L40: 30000
